Workbook

Sheet DCF
C2: Historicals | F2: Forecasts | L2: Gordon Growth Method
B3: In USD millions | C3: 2023 | D3: =C3+1 | E3: =D3+1 | F3: =E3+1 | G3: =F3+1 | H3: =G3+1 | I3: =H3+1 | J3: =I3+1 | L3: Terminal-Year UFCF (normalized) | M3: =J4*M6
B4: Total Revenue | C4: ='Revenue Build'!C9 | D4: ='Revenue Build'!D9 | E4: ='Revenue Build'!E9 | F4: ='Revenue Build'!F9 | G4: ='Revenue Build'!G9 | H4: ='Revenue Build'!H9 | I4: ='Revenue Build'!I9 | J4: ='Revenue Build'!J9 | L4: Perpetuity Growth Rate | M4: 0.03
B5: % Growth | D5: =D4/C4-1 | E5: =E4/D4-1 | F5: =F4/E4-1 | G5: =G4/F4-1 | H5: =H4/G4-1 | I5: =I4/H4-1 | J5: =J4/I4-1 | L5: TV FCF | M5: =M3*(1+M4)
B6: COGS | C6: ='Annual IS'!B9 | D6: ='Annual IS'!C9 | E6: ='Annual IS'!D9 | F6: =F4*F32 | G6: =G4*G32 | H6: =H4*H32 | I6: =I4*I32 | J6: =J4*J32 | L6: Terminal UFCF Margin (normalized) | M6: 0.1
B7: Gross profit | C7: =C4-C6 | D7: =D4-D6 | E7: =E4-E6 | F7: =F4-F6 | G7: =G4-G6 | H7: =H4-H6 | I7: =I4-I6 | J7: =J4-J6 | L7: TV | M7: =M5/('WACC Calculations'!C13-M4)
B8: Gross Profit Margin | C8: =C7/C4 | D8: =D7/D4 | E8: =E7/E4 | F8: =F7/F4 | G8: =G7/G4 | H8: =H7/H4 | I8: =I7/I4 | J8: =J7/J4
B9: Hour-driven G&A (insurance, support) | C9: ='Revenue Build'!C5*C33 | D9: ='Revenue Build'!D5*D33 | E9: ='Revenue Build'!E5*E33 | F9: ='Revenue Build'!F5*F33 | G9: ='Revenue Build'!G5*G33 | H9: ='Revenue Build'!H5*H33 | I9: ='Revenue Build'!I5*I33 | J9: ='Revenue Build'!J5*J33 | L9: PV of TV | M9: =M7/(1+F24)^(F23+4)
B10: Fixed opex (other G&A, S&M, R&D) | C10: ='Annual IS'!B17-C9-C11 | D10: ='Annual IS'!C17-D9-D11 | E10: ='Annual IS'!D17-E9-E11 | F10: =E10*(1+F34) | G10: =F10*(1+G34) | H10: =G10*(1+H34) | I10: =H10*(1+I34) | J10: =I10*(1+J34) | L10: PV of FCF | M10: =SUM(F28:J28)
B11: Stock-based comp (in opex) | C11: ='Annual IS'!B93-'Annual IS'!B89 | D11: ='Annual IS'!C93-'Annual IS'!C89 | E11: ='Annual IS'!D93-'Annual IS'!D89 | F11: =F4*F35 | G11: =G4*G35 | H11: =H4*H35 | I11: =I4*I35 | J11: =J4*J35
B12: OpEx | C12: =SUM(C9:C11) | D12: =SUM(D9:D11) | E12: =SUM(E9:E11) | F12: =SUM(F9:F11) | G12: =SUM(G9:G11) | H12: =SUM(H9:H11) | I12: =SUM(I9:I11) | J12: =SUM(J9:J11) | L12: Implied EV | M12: =M10+M9
B13: EBIT | C13: =C7-C12 | D13: =D7-D12 | E13: =E7-E12 | F13: =F7-F12 | G13: =G7-G12 | H13: =H7-H12 | I13: =I7-I12 | J13: =J7-J12
B14: EBIT Margin | C14: =C13/C4 | D14: =D13/D4 | E14: =E13/E4 | F14: =F13/F4 | G14: =G13/G4 | H14: =H13/H4 | I14: =I13/I4 | J14: =J13/J4 | L14: (+) Cash | M14: ='Key Stats'!B63
B15: (-) Income Tax Expense | C15: ='Annual IS'!B33 | D15: ='Annual IS'!C33 | E15: ='Annual IS'!D33 | F15: =MAX(F13,0)*F36 | G15: =MAX(G13,0)*G36 | H15: =MAX(H13,0)*H36 | I15: =MAX(I13,0)*I36 | J15: =MAX(J13,0)*J36 | L15: (-) Debt | M15: 0
B16: NOPAT | C16: =C13-C15 | D16: =D13-D15 | E16: =E13-E15 | F16: =F13-F15 | G16: =G13-G15 | H16: =H13-H15 | I16: =I13-I15 | J16: =J13-J15 | L16: Implied Equity Value | M16: =M12+M14-M15
B17: (+) D&A | C17: 8.02 | D17: 9.126 | E17: 8.529 | F17: =F4*F37 | G17: =G4*G37 | H17: =H4*H37 | I17: =I4*I37 | J17: =J4*J37
B18: (+) SBC (historical only) | C18: ='Annual IS'!B93 | D18: ='Annual IS'!C93 | E18: ='Annual IS'!D93 | F18: 0 | G18: 0 | H18: 0 | I18: 0 | J18: 0 | L18: Shares Outstanding | M18: ='WACC Calculations'!C27
B19: (-) Changes in NWC | C19: -0.095 | D19: -15.22 | E19: 3.355 | F19: =F4*F38 | G19: =G4*G38 | H19: =H4*H38 | I19: =I4*I38 | J19: =J4*J38
B20: (-) CapEx | C20: -4.802 | D20: -4.451 | E20: -5.914 | F20: =-F4*F39 | G20: =-G4*G39 | H20: =-H4*H39 | I20: =-I4*I39 | J20: =-J4*J39 | L20: Implied Stock Price | M20: =M16/M18
B21: UFCF | C21: =SUM(C16:C20) | D21: =SUM(D16:D20) | E21: =SUM(E16:E20) | F21: =SUM(F16:F20) | G21: =SUM(G16:G20) | H21: =SUM(H16:H20) | I21: =SUM(I16:I20) | J21: =SUM(J16:J20) | L21: Current Stock Price | M21: ='WACC Calculations'!C15
B22: UFCF Margin | C22: =C21/C4 | D22: =D21/D4 | E22: =E21/E4 | F22: =F21/F4 | G22: =G21/G4 | H22: =H21/H4 | I22: =I21/I4 | J22: =J21/J4 | L22: Implied Upside/(Downside) | M22: =M20/M21-1
B23: Stub Period Fraction | F23: =(DATE(F$3,12,31)-$M$23)/365 | G23: 1 | H23: 1 | I23: 1 | J23: 1 | L23: Valuation Date | M23: =DATE(2026,9,10)
B24: WACC | F24: ='WACC Calculations'!$C$13 | G24: =F24 | H24: =G24 | I24: =H24 | J24: =I24
B25: Discount Period | F25: =F23/2 | G25: =F23+0.5 | H25: =G25+1 | I25: =H25+1 | J25: =I25+1 | L25: Exit Multiple Method
B26: Discount Factor | F26: =(1+F24)^F25 | G26: =(1+G24)^G25 | H26: =(1+H24)^H25 | I26: =(1+I24)^I25 | J26: =(1+J24)^J25 | L26: Last Year Revenue | M26: =J4
B27: UFCF Counted (x Stub Fraction) | F27: =F21*F23 | G27: =G21*G23 | H27: =H21*H23 | I27: =I21*I23 | J27: =J21*J23 | L27: Terminal EV/Revenue Multiple | M27: 2.5
B28: NPV of UFCF | F28: =F27/F26 | G28: =G27/G26 | H28: =H27/H26 | I28: =I27/I26 | J28: =J27/J26 | L28: TV | M28: =M27*M26
B29: Diluted Shares Outstanding (mm) | C29: ='Annual IS'!B55 | D29: ='Annual IS'!C55 | E29: ='Annual IS'!D55 | F29: ='WACC Calculations'!C27*(1+F40) | G29: =F29*(1+G40) | H29: =G29*(1+H40) | I29: =H29*(1+I40) | J29: =I29*(1+J40)
L30: PV of TV | M30: =M28/(1+F24)^(F23+4)
B31: Drivers | L31: PV of FCF | M31: =SUM(F28:J28)
B32: COGS as a % of Revenue | C32: =C6/C4 | D32: =D6/D4 | E32: =E6/E4 | F32: =1-'Revenue Build'!F31 | G32: =1-'Revenue Build'!G31 | H32: =1-'Revenue Build'!H31 | I32: =1-'Revenue Build'!I31 | J32: =1-'Revenue Build'!J31 | L32: Implied EV | M32: =M31+M30
B33: Hour-driven G&A (% of services revenue) | C33: 0.065 | D33: 0.065 | E33: 0.065 | F33: 0.065 | G33: 0.065 | H33: 0.065 | I33: 0.065 | J33: 0.065
B34: Fixed opex growth | D34: =D10/C10-1 | E34: =E10/D10-1 | F34: 0.08 | G34: 0.04 | H34: 0.04 | I34: 0.04 | J34: 0.04 | L34: (+) Cash | M34: =M14
B35: SBC as a % of Revenue | C35: =C11/C4 | D35: =D11/D4 | E35: =E11/E4 | F35: 0.12 | G35: 0.1 | H35: 0.08 | I35: 0.07 | J35: 0.06 | L35: (-) Debt | M35: =M15
B36: Effective Tax Rate | C36: =IF(C13>0,C15/C13,0) | D36: =IF(D13>0,D15/D13,0) | E36: =IF(E13>0,E15/E13,0) | F36: 0.21 | G36: 0.21 | H36: 0.21 | I36: 0.21 | J36: 0.21 | L36: Implied Equity Value | M36: =M32+M34-M35
B37: D&A as a % of Revenue | C37: =C17/C4 | D37: =D17/D4 | E37: =E17/E4 | F37: 0.018 | G37: 0.018 | H37: 0.018 | I37: 0.018 | J37: 0.018
B38: Changes in NWC as a % of Revenue | C38: =C19/C4 | D38: =D19/D4 | E38: =E19/E4 | F38: -0.015 | G38: -0.015 | H38: -0.015 | I38: -0.015 | J38: -0.015 | L38: Shares Outstanding | M38: =M18
B39: Capex as a % of Revenue | C39: =-C20/C4 | D39: =-D20/D4 | E39: =-E20/E4 | F39: 0.014 | G39: 0.014 | H39: 0.014 | I39: 0.014 | J39: 0.014
B40: Diluted Share Count Growth | F40: 0.025 | G40: 0.025 | H40: 0.025 | I40: 0.025 | J40: 0.025 | L40: Implied Stock Price | M40: =M36/M38
L41: Current Stock Price | M41: =M21
...

Sheet Revenue Build
C2: Historicals | F2: Forecasts
B3: Revenue ($ millions) | C3: 2023 | D3: =C3+1 | E3: =D3+1 | F3: =E3+1 | G3: =F3+1 | H3: =G3+1 | I3: =H3+1 | J3: =I3+1
B4: Software (platform) | C4: 57.9 | D4: 78.6 | E4: 101.1 | F4: =E4*(1+F19) | G4: =F4*(1+G19) | H4: =G4*(1+H19) | I4: =H4*(1+I19) | J4: =I4*(1+J19)
B5: Services | C5: =C6+C7 | D5: =D6+D7 | E5: =E6+E7 | F5: =F6+F7 | G5: =G6+G7 | H5: =H6+H7 | I5: =I6+I7 | J5: =J6+J7
B6: Microtransit & paratransit | C6: =C9-C8-C4-C7 | D6: =D9-D8-D4-D7 | E6: =E9-E8-E4-E7 | F6: =E6*(1+F20) | G6: =F6*(1+G20) | H6: =G6*(1+H20) | I6: =H6*(1+I20) | J6: =I6*(1+J20)
B7: Network deals | C7: 0 | D7: 11.1 | E7: 14.4 | F7: =E22+0.5*F21 | G7: =F22+0.5*G21 | H7: =G22+0.5*H21 | I7: =H22+0.5*I21 | J7: =I22+0.5*J21
B8: One-time (implementation, consulting) | C8: =C9*C23 | D8: =D9*D23 | E8: =E9*E23 | F8: =(F4+F5)*F23/(1-F23) | G8: =(G4+G5)*G23/(1-G23) | H8: =(H4+H5)*H23/(1-H23) | I8: =(I4+I5)*I23/(1-I23) | J8: =(J4+J5)*J23/(1-J23)
B9: Total net revenue | C9: ='Annual IS'!B7 | D9: ='Annual IS'!C7 | E9: ='Annual IS'!D7 | F9: =F4+F5+F8 | G9: =G4+G5+G8 | H9: =H4+H5+H8 | I9: =I4+I5+I8 | J9: =J4+J5+J8
B10: % growth | D10: =D9/C9-1 | E10: =E9/D9-1 | F10: =F9/E9-1 | G10: =G9/F9-1 | H10: =H9/G9-1 | I10: =I9/H9-1 | J10: =J9/I9-1
B11: Consensus | C11: =C9 | D11: =D9 | E11: =E9 | F11: ='Consensus (BBG)'!P7 | G11: ='Consensus (BBG)'!Q7 | H11: ='Key Stats'!H16
B12: % growth | D12: =D11/C11-1 | E12: =E11/D11-1 | F12: =F11/E11-1 | G12: =G11/F11-1 | H12: =H11/G11-1
B13: Model vs consensus | F13: =F9/F11-1 | G13: =G9/G11-1 | H13: =H9/H11-1
B14: Services % of revenue | C14: =C5/C9 | D14: =D5/D9 | E14: =E5/E9 | F14: =F5/F9 | G14: =G5/G9 | H14: =H5/H9 | I14: =I5/I9 | J14: =J5/J9
B15: Network deals % of revenue | C15: =C7/C9 | D15: =D7/D9 | E15: =E7/E9 | F15: =F7/F9 | G15: =G7/G9 | H15: =H7/H9 | I15: =I7/I9 | J15: =J7/J9
B16: Network deals share of revenue growth | D16: =(D7-C7)/(D9-C9) | E16: =(E7-D7)/(E9-D9) | F16: =(F7-E7)/(F9-E9) | G16: =(G7-F7)/(G9-F9) | H16: =(H7-G7)/(H9-G9) | I16: =(I7-H7)/(I9-H9) | J16: =(J7-I7)/(J9-I9)
B18: DRIVERS
B19: Software revenue % growth | D19: =D4/C4-1 | E19: =E4/D4-1 | F19: 0.12 | G19: 0.11 | H19: 0.1 | I19: 0.09 | J19: 0.08
B20: Microtransit & paratransit % growth | D20: =D6/C6-1 | E20: =E6/D6-1 | F20: 0.25 | G20: 0.16 | H20: 0.12 | I20: 0.1 | J20: 0.08
B21: Network: new contract value launched ($mm) | D21: =D22-C22 | E21: =E22-D22 | F21: 20 | G21: 40 | H21: 60 | I21: 70 | J21: 80
B22: Network: contract run-rate, year-end ($mm) | C22: 0 | D22: 11.1 | E22: 23.5 | F22: =E22+F21 | G22: =F22+G21 | H22: =G22+H21 | I22: =H22+I21 | J22: =I22+J21
B23: One-time revenue % of total | C23: 0.03 | D23: 0.03 | E23: 0.03 | F23: 0.03 | G23: 0.03 | H23: 0.03 | I23: 0.03 | J23: 0.03
B25: GROSS MARGIN BY STREAM
B26: Software | F26: 0.75 | G26: 0.75 | H26: 0.75 | I26: 0.75 | J26: 0.75
B27: Microtransit & paratransit | F27: 0.293 | G27: 0.293 | H27: 0.293 | I27: 0.293 | J27: 0.293
B28: Network deals | F28: 0.25 | G28: 0.25 | H28: 0.25 | I28: 0.25 | J28: 0.25
B29: One-time | F29: 0.75 | G29: 0.75 | H29: 0.75 | I29: 0.75 | J29: 0.75
B30: Gross profit ($mm) | C30: ='Annual IS'!B10 | D30: ='Annual IS'!C10 | E30: ='Annual IS'!D10 | F30: =F4*F26+F6*F27+F7*F28+F8*F29 | G30: =G4*G26+G6*G27+G7*G28+G8*G29 | H30: =H4*H26+H6*H27+H7*H28+H8*H29 | I30: =I4*I26+I6*I27+I7*I28+I8*I29 | J30: =J4*J26+J6*J27+J7*J28+J8*J29
B31: Gross margin | C31: =C30/C9 | D31: =D30/D9 | E31: =E30/E9 | F31: =F30/F9 | G31: =G30/G9 | H31: =H30/H9 | I31: =I30/I9 | J31: =J30/J9
B32: Consensus gross margin | C32: =C31 | D32: =D31 | E32: =E31 | F32: ='Consensus (BBG)'!P23 | G32: ='Consensus (BBG)'!Q23 | H32: ='Key Stats'!H20

Sheet WACC Calculations
B2: WACC Calculations
B3: Debt | C3: /
B4: Equity | C4: =C17
B5: % Debt | C5: 0
B6: % Equity | C6: 1
B7: Cost of Debt | C7: /
B8: After-Tax Cost of Debt | C8: /
B9: Cost of Equity | C9: =C10+(C11*C12)
B10: US 10Y Treasury Yield | C10: 0.0483
B11: Beta | C11: 1.03
B12: Market Risk Premium | C12: 0.0446
B13: WACC | C13: =C9
B15: Share Price ($) | C15: 29.98
B16: Shares Oustanding (mm) | C16: ='Key Stats'!B51
B17: Market Cap (mm) | C17: =C15*C16
B20: Diluted Shares
B21: Basic shares outstanding (mm) | C21: =C16
B22: Options outstanding (mm) | C22: 8.901695
B23: Weighted-avg. exercise price ($) | C23: 13.94
B24: Net shares from options (mm) | C24: =C22*MAX(0,1-C23/C15)
B25: Unvested RSUs (mm) | C25: 3.750862
B26: PSUs | C26: 0
B27: Diluted Shares Outstanding (mm) | C27: =C21+C24+C25+C26

Sheet Supporting Tabs >>>

Sheet Consensus (BBG)
A1: Via Transportation Inc- Company Financial (Multiple Periods) | P1: Source: Bloomberg consensus (VIA US Equity), quarterly. FY columns sum the four quarters (FY26 includes Q1-Q2 2026 actuals).
A2: VIA US Equity Periodicity:Q Currency:USD Estimate Source:BST Actual Source:Bloomberg
A3: In Millions of USD | E3: 2025 Q3 (Rep) | F3: 2025 Q4 (Rep) | G3: 2026 Q1 (Rep) | H3: 2026 Q2 (Rep) | I3: 2026 Q3 (Fwd) | J3: 2026 Q4 (Fwd) | K3: 2027 Q1 (Fwd) | L3: 2027 Q2 (Fwd) | M3: 2027 Q3 (Fwd) | N3: 2027 Q4 (Fwd) | P3: FY2026E | Q3: FY2027E
A4: 3 Months Ending | B4: Field Expression | C4: Calcrt Field | D4: Segment Id | E4: 45930 | F4: 46022 | G4: 46112 | H4: 46203 | I4: 46295 | J4: 46387 | K4: 46477 | L4: 46568 | M4: 46660 | N4: 46752 | P4: Sum of Q1-Q4 | Q4: Sum of Q1-Q4
A5: Highlights
A6: Adjusted Diluted EPS | B6: IS_COMP_EPS_ADJUSTED_OLD | C6: IS900 | E6: -0.127926 | F6: -0.05921 | G6: -0.05 | H6: -0.010282 | I6: -0.0272 | J6: 0.0473 | K6: 0.0558 | L6: 0.0971 | M6: 0.1083 | N6: 0.1539
A7: Revenue | B7: IS_COMP_SALES | C7: IS902 | E7: 109.653 | F7: 118.909 | G7: 127.434 | H7: 135.707 | I7: 138 | J7: 150.55556 | K7: 156.66667 | L7: 167.44444 | M7: 169.11111 | N7: 181.55556 | P7: =SUM(G7:J7) | Q7: =SUM(K7:N7)
A9: Operating Income | B9: IS_COMPARABLE_EBIT | C9: IM132 | E9: -18.891 | F9: -24.391 | G9: -23.584 | H9: -21.754 | I9: -21.525 | J9: -15.75 | K9: -14.66125 | L9: -11.1575 | M9: -10.58375 | N9: -7.3075
A10: Adjusted EBITDA | B10: IS_COMPARABLE_EBITDA | C10: IM131 | E10: -8.692 | F10: -7.384 | G10: -5.809 | H10: -0.003441 | I10: -4.0322222 | J10: 2.4097778 | K10: 3.4154444 | L10: 6.9811111 | M10: 7.79 | N10: 11.256667 | P10: =SUM(G10:J10) | Q10: =SUM(K10:N10)
A11: Adjusted Net Income | B11: IS_COMP_NET_INCOME_ADJUST_OLD | C11: IS903 | E11: -9.684 | F11: -4.796 | G11: -3.771 | H11: -0.838 | I11: -4.1111111 | J11: 2.1888889 | K11: 3.2643333 | L11: 7.1233333 | M11: 7.9644444 | N11: 11.425556
A13: Business Breakdown
A14: Customer Count | B14: NUMBER_OF_CUSTOMERS | C14: M6307 | D14: SEG6561238188 Segment | G14: 0.838 | H14: 0.847 | I14: 0.862 | J14: 0.888 | K14: 0.909 | L14: 0.923 | M14: 0.94 | N14: 0.962
A16: Platform Annual Run-Rate Revenue | B16: SALES_REV_TURN | C16: IS010 | D16: SEG9057071857 Segment | E16: 109.653 | G16: 509.736 | H16: 542.828
A18: Income Statement
A19: Total Revenue | B19: IS_COMP_SALES | C19: IS902 | E19: 109.653 | F19: 118.909 | G19: 127.434 | H19: 135.707 | I19: 138 | J19: 150.55556 | K19: 156.66667 | L19: 167.44444 | M19: 169.11111 | N19: 181.55556
A21: Cost of Revenue | B21: IS_COGS_TO_FE_AND_PP_AND_G | C21: IS021 | E21: 66.567 | F21: 71.956 | G21: 77.379 | H21: 80.101 | I21: 83.211666 | J21: 90.352505 | K21: 93.624765 | L21: 99.293944 | M21: 99.948153 | N21: 106.55178
A22: Gross Profit | B22: CB_IS_GROSS_PROFIT | C22: IC399 | E22: 43.086 | F22: 46.953 | G22: 50.055 | H22: 55.606 | I22: 54.725621 | J22: 60.265998 | K22: 63.131057 | L22: 68.097072 | M22: 69.145007 | N22: 75.005961 | P22: =SUM(G22:J22) | Q22: =SUM(K22:N22)
A23: Gross Margin (%) | B23: IS_COMP_GROSS_MARGIN_PERCENTAGE | C23: IM092 | E23: 40 | F23: 39.86578 | G23: 40 | H23: 41 | I23: 39.814126 | J23: 40.144826 | K23: 40.373965 | L23: 40.750632 | M23: 40.962324 | N23: 41.37826 | P23: =P22/P7 | Q23: =Q22/Q7
A25: Total Operating Expenses | B25: IS_OPERATING_EXPN | C25: IS032 | E25: 61.977 | F25: 71.344 | G25: 73.639 | H25: 77.36 | I25: 75.877208 | J25: 76.113875 | K25: 76.702573 | L25: 78.26794 | M25: 78.316136 | N25: 81.6391
A26: As % of Revenue | B26: OPERATING_EXPENSES_TO_NET_SALES | C26: RR280 | E26: 56.521025 | F26: 59.998823 | G26: 57.785991 | H26: 57.005166 | I26: 54.688393 | J26: 51.535505 | K26: 51.096447 | L26: 49.024018 | M26: 48.388347 | N26: 46.402614
A27: Research & Development | B27: IS_OPEX_R_AND_D_GAAP | C27: IM441 | E27: 23.131 | F27: 25.138 | G27: 24.528 | H27: 26.108 | I27: 25.943142 | J27: 25.936699 | K27: 26.175263 | L27: 26.843024 | M27: 26.852701 | N27: 28.081873
A28: As % of Revenue | B28: RD_EXPEND_TO_NET_SALES | C28: RR295 | E28: 21.094726 | F28: 21.140536 | G28: 19.247611 | H28: 19.238506 | I28: 18.900946 | J28: 17.337263 | K28: 17.025867 | L28: 16.342758 | M28: 16.145862 | N28: 15.839969
A29: Sales & Marketing | B29: CB_IS_S_AND_M_EXPENSE | C29: IM736 | E29: 17.657 | F29: 18.591 | G29: 20.49 | H29: 21.142 | I29: 20.405977 | J29: 20.323802 | K29: 20.788773 | L29: 21.591884 | M29: 21.750266 | N29: 22.48428
A30: General & Administrative | B30: CB_IS_GENL_AND_ADMIN_EXPN | C30: IM737 | E30: 21.189 | F30: 27.615 | G30: 28.621 | H30: 30.11 | I30: 29.174292 | J30: 29.348421 | K30: 29.312821 | L30: 29.721998 | M30: 29.749285 | N30: 30.559738
A32: Depreciation & Amortization | B32: CF_DEPR_AMORT | C32: CF011 | E32: 2.133 | F32: 2.053 | G32: 2.399 | H32: 2.38 | I32: 2.5049788 | J32: 2.3744769 | K32: 1.86643 | L32: 1.6622628 | M32: 1.6626765 | N32: 1.7197502
A33: Amortization | B33: CB_IS_AMORT_INTANG_ASSET_ATTR_OP_EX | C33: IL286 | E33: 1.1 | F33: 1.1 | G33: 1.412 | H33: 1.38 | I33: 1.1289915 | J33: 1.1370473 | K33: 0.97398159 | L33: 0.76939823 | M33: 0.74977451 | N33: 0.75963067
A35: Operating Income | B35: IS_COMPARABLE_EBIT | C35: IM132 | E35: -18.891 | F35: -24.391 | G35: -23.584 | H35: -21.754 | I35: -21.525 | J35: -15.75 | K35: -14.66125 | L35: -11.1575 | M35: -10.58375 | N35: -7.3075
A36: Operating Margin (%) | B36: OPER_MARGIN | C36: RR026 | E36: -17.227983 | F36: -20.512325 | G36: -18.506835 | H36: -16.030124 | I36: -15.63721 | J36: -10.54657 | K36: -9.7129102 | L36: -6.8244943 | M36: -6.58398 | N36: -4.4346394
A38: EBITDA | B38: IS_COMPARABLE_EBITDA | C38: IM131 | E38: -8.692 | F38: -7.384 | G38: -5.809 | H38: -0.003441 | I38: -4.0322222 | J38: 2.4097778 | K38: 3.4154444 | L38: 6.9811111 | M38: 7.79 | N38: 11.256667
A40: Interest Expense (Income), Net | B40: IS_NET_INTEREST_EXPENSE | C40: IS325 | E40: 1.264 | F40: -2.964 | G40: -2.55 | H40: -2.517 | I40: -2.3281307 | J40: -2.3313999 | K40: -2.4416419 | L40: -2.4333148 | M40: -2.4498054 | N40: -2.5072543
... A54: Diluted EPS | B54: IS_COMP_EPS_GAAP | C54: IS901 | E54: -0.487279 | F54: -0.270815 | G54: -0.25 | H54: -0.24 | I54: -0.2425 | J54: -0.17 | K54: -0.15625 | L54: -0.1105 | M54: -0.101625 | N54: -0.06275
A56: Adjusted Results
A57: Net Income | B57: IS_COMP_NET_INCOME_ADJUST_OLD | C57: IS903 | E57: -9.684 | F57: -4.796 | G57: -3.771 | H57: -0.838 | I57: -4.1111111 | J57: 2.1888889 | K57: 3.2643333 | L57: 7.1233333 | M57: 7.9644444 | N57: 11.425556
A58: Diluted EPS | B58: IS_COMP_EPS_ADJUSTED_OLD | C58: IS900 | E58: -0.127926 | F58: -0.05921 | G58: -0.05 | H58: -0.010282 | I58: -0.0272 | J58: 0.0473 | K58: 0.0558 | L58: 0.0971 | M58: 0.1083 | N58: 0.1539
A60: Company Specific Adjustments
A61: Stock-Based Compensation | B61: CF_STOCK_BASED_COMPENSATION | C61: CF283 | E61: 6.592 | F61: 14.396 | G61: 15.564 | H61: 16.01 | I61: 15.580766 | J61: 16.159412 | K61: 15.935029 | L61: 16.110417 | M61: 16.225805 | N61: 16.543295
A62: Cost of Goods Sold | B62: IS_SBC_ATTRIB_TO_COGS_PRETX | C62: IM496 | E62: 0.038 | F62: 0.056 | G62: 0.075 | H62: 0.098 | I62: 0.093799452 | J62: 0.10061384 | K62: 0.10818837 | L62: 0.10898681 | M62: 0.10915316 | N62: 0.11168595
A63: Research & Development | B63: IS_SBC_ATTRIBUTABLE_TO_R_AND_D_PRETX | C63: IM494 | E63: 1.874 | F63: 3.54 | G63: 4.03 | H63: 4.302 | I63: 3.9572779 | J63: 3.9782008 | K63: 3.7168595 | L63: 3.744109 | M63: 3.796552 | N63: 3.909138
A64: Selling & Marketing | B64: IS_SBC_ATT_TO_S_AND_M_PRETX | C64: IM498 | E64: 1.687 | F64: 2.895 | G64: 3.328 | H64: 3.623 | I64: 3.1114576 | J64: 3.1286276 | K64: 3.191743 | L64: 3.2566368 | M64: 3.307942 | N64: 3.359073
A65: General & Administrative | B65: IS_SBC_ATT_TO_GENL_AND_ADMIN_PRETX | C65: IM497 | E65: 2.993 | F65: 7.905 | G65: 8.131 | H65: 7.987 | I65: 8.3911118 | J65: 8.9524793 | K65: 8.8966292 | L65: 8.9896109 | M65: 9.0190157 | N65: 9.1763904
...

Sheet Annual IS
A1: Income Statement
A2: For the Fiscal Period Ending | B2: 12 months Dec-31-2023 | C2: 12 months Dec-31-2024 | D2: 12 months Dec-31-2025 | E2: LTM 12 months Jun-30-2026
A3: Currency | B3: USD | C3: USD | D3: USD | E3: USD
A5: Revenue | B5: 248.854 | C5: 337.63 | D5: 434.337 | E5: 491.703
A6: Other Revenue | B6: - | C6: - | D6: - | E6: -
A7: Total Revenue | B7: 248.854 | C7: 337.63 | D7: 434.337 | E7: 491.703
A9: Cost Of Goods Sold | B9: 149.446 | C9: 206.79 | D9: 262.534 | E9: 296
A10: Gross Profit | B10: 99.408 | C10: 130.84 | D10: 171.803 | E10: 195.703
A12: Selling General & Admin Exp. | B12: 118.03 | C12: 125.749 | D12: 155.205 | E12: 184.556
A13: R & D Exp. | B13: 95.833 | C13: 88.987 | D13: 92.303 | E13: 98.856
A14: Depreciation & Amort. | B14: - | C14: - | D14: - | E14: -
A15: Other Operating Expense/(Income) | B15: - | C15: - | D15: 0.911 | E15: 0.911
A17: Other Operating Exp., Total | B17: 213.863 | C17: 214.736 | D17: 248.419 | E17: 284.323
A19: Operating Income | B19: -114.5 | C19: -83.9 | D19: -76.6 | E19: -88.6
A21: Interest Expense | B21: -0.7 | C21: -4.3 | D21: -7.3 | E21: -3
A22: Interest and Invest. Income | B22: 3.599 | C22: 2.195 | D22: 5.272 | E22: 9.796
A23: Net Interest Exp. | B23: 2.946 | C23: -2.1 | D23: -2.1 | E23: 6.767
A25: Currency Exchange Gains (Loss) | B25: -1.5 | C25: 0.326 | D25: 0.475 | E25: -1.3
A26: Other Non-Operating Inc. (Exp.) | B26: -2.1 | C26: -4.9 | D26: -7.2 | E26: -5.2
A27: EBT Excl. Unusual Items | B27: -115.1 | C27: -90.5 | D27: -85.4 | E27: -88.4
A29: Impairment of Goodwill | B29: - | C29: - | D29: - | E29: -
A30: Other Unusual Items | B30: - | C30: 1.857 | D30: -8.5 | E30: -8.5
A31: EBT Incl. Unusual Items | B31: -115.1 | C31: -88.7 | D31: -93.8 | E31: -96.9
A33: Income Tax Expense | B33: 1.815 | C33: 1.89 | D33: 2.521 | E33: 1.599
A34: Earnings from Cont. Ops. | B34: -117 | C34: -90.6 | D34: -96.4 | E34: -98.5
A36: Earnings of Discontinued Ops. | B36: - | C36: - | D36: - | E36: -
A37: Extraord. Item & Account. Change | B37: - | C37: - | D37: - | E37: -
A38: Net Income to Company | B38: -117 | C38: -90.6 | D38: -96.4 | E38: -98.5
A40: Minority Int. in Earnings | B40: 0.278 | C40: 0.271 | D40: - | E40: -
A41: Net Income | B41: -116.7 | C41: -90.3 | D41: -96.4 | E41: -98.5
A43: Pref. Dividends and Other Adj. | B43: - | C43: - | D43: - | E43: -
A45: NI to Common Incl Extra Items | B45: -116.7 | C45: -90.3 | D45: -96.4 | E45: -98.5
A46: NI to Common Excl. Extra Items | B46: -116.7 | C46: -90.3 | D46: -96.4 | E46: -98.5
A48: Per Share Items
A49: Basic EPS | B49: -9.6 | C49: -7.21 | D49: -2.92 | E49: -1.47
A50: Basic EPS Excl. Extra Items | B50: -9.6 | C50: -7.21 | D50: -2.92 | E50: -1.47
A51: Weighted Avg. Basic Shares Out. | B51: 12.15567 | C51: 12.525706 | D51: 32.949511 | E51: 67.181601
A53: Diluted EPS | B53: -9.6 | C53: -7.21 | D53: -2.92 | E53: -1.47
A54: Diluted EPS Excl. Extra Items | B54: -9.6 | C54: -7.21 | D54: -2.92 | E54: -1.47
A55: Weighted Avg. Diluted Shares Out. | B55: 12.15567 | C55: 12.525706 | D55: 32.949511 | E55: 67.181601
...

Sheet Key Stats
A5: Via Transportation, Inc. (NYSE:VIA) > Financials > Key Stats
A7: In Millions of the trading currency, except per share items. | B7: Currency: | C7: Trading Currency | E7: Conversion: | F7: Historical
B8: Order: | C8: Latest on Right | E8: Units: | F8: S&P Capital IQ (Default)
B9: Decimals: | C9: Capital IQ (Default) | E9: Dilution: | F9: Basic
A12: Key Financials¹
A13: For the Fiscal Period Ending | B13: 12 months Dec-31-2023A | C13: 12 months Dec-31-2024A | D13: 12 months Dec-31-2025A | E13: LTM² 12 months Jun-30-2026A | F13: 12 months† Dec-31-2026E | G13: 12 months Dec-31-2027E | H13: 12 months Dec-31-2028E
A14: Currency | B14: USD | C14: USD | D14: USD | E14: USD | F14: USD | G14: USD | H14: USD
A16: Total Revenue | B16: 248.854 | C16: 337.63 | D16: 434.337 | E16: 491.703 | F16: 551.73774 | G16: 674.03932 | H16: 814.01794
A17: Growth Over Prior Year | B17: NA | C17: 0.356739 | D17: 0.286428 | E17: 0.291328 | F17: 0.27029873 | G17: 0.22166615 | H17: 0.2076713
A19: Gross Profit | B19: 99.408 | C19: 130.84 | D19: 171.803 | E19: 195.703 | F19: - | G19: - | H19: -
A20: Margin % | B20: 0.399463 | C20: 0.387524 | D20: 0.395552 | E20: 0.39801 | F20: 0.403 | G20: 0.409875 | H20: 0.4195
A22: EBITDA | B22: -106.4 | C22: -74.8 | D22: -68.1 | E22: -79.7 | F22: -10.78 | G22: 30.0682 | H22: 67.45326
A23: Margin % | B23: -0.4277 | C23: -0.221455 | D23: -0.15676 | E23: -0.161998 | F23: - | G23: 0.04460897 | H23: 0.082864586
A25: EBIT | B25: -114.5 | C25: -83.9 | D25: -76.6 | E25: -88.6 | F25: -81.17 | G25: -45.42 | H25: -21.93
A26: Margin % | B26: -0.459928 | C26: -0.248485 | D26: -0.176397 | E26: -0.18023 | F26: - | G26: - | H26: -
A28: Earnings from Cont. Ops. | B28: -117 | C28: -90.6 | D28: -96.4 | E28: -98.5 | F28: - | G28: - | H28: -
A29: Margin % | B29: -0.47001 | C29: -0.268198 | D29: -0.221857 | E29: -0.200381 | F29: - | G29: - | H29: -
A31: Net Income | B31: -116.7 | C31: -90.3 | D31: -96.4 | E31: -98.5 | F31: -2.55 | G31: 37.93337 | H31: 73.18674
A32: Margin % | B32: -0.468893 | C32: -0.267396 | D32: -0.221857 | E32: -0.200381 | F32: -0.0046256941 | G32: 0.056277681 | H32: 0.089908018
A34: Diluted EPS Excl. Extra Items³ | B34: -9.6 | C34: -7.21 | D34: -2.92 | E34: -1.47 | F34: -0.03 | G34: 0.42981 | H34: 0.79631
A35: Growth Over Prior Year | B35: NA | C35: NM | D35: NM | E35: NM | F35: - | G35: - | H35: 0.85270236
A38: Currency | B38: USD | C38: USD | D38: USD | E38: USD | F38: USD | G38: USD | H38: USD
A39: Exchange Rate | B39: 1 | C39: 1 | D39: 1 | E39: 1 | F39: 1 | G39: 1 | H39: 1
A40: Conversion Method | B40: H | C40: H | D40: H | E40: H | F40: S | G40: S | H40: S
A42: ¹All results are taken from the most recently filed statement for each period. When there has been more than one, earlier filings can be viewed on the individual statement pages.
A43: ²Growth rates for the LTM period are calculated against the LTM period ending 12 months before.
A44: ³All forward period figures are consensus mean estimates provided by the brokers and may not be on a comparable basis as financials.
A45: †Growth rates for forward periods are calculated against prior period estimates or actual pro forma results as disclosed on the Estimates Consensus page.
A46: Growth Rates are calculated in originally reported currency only and will not reflect any currency conversion selected above.
A48: Current Capitalization (Millions of USD)
A49: Currency | B49: USD
A50: Share Price | B50: 27.98
A51: Shares Out. | B51: 81.505613
A53: Market Capitalization | B53: 2280.5271
A54: Class A Common Stock Shares Out | B54: 77.65943
A55: * Class A Common Stock Share Price | B55: 27.98
A56: = Class A Common Stock Market Capitalization | B56: 2172.9109
A57: + Class B Common Stock Shares Out | B57: 3.846183
A58: * Class B Common Stock Share Price | B58: 27.98
A59: = Class B Common Stock Market Capitalization | B59: 107.6162
...

Sheet Quarterly IS
A1: Income Statement
A2: For the Fiscal Period Ending | B2: 3 months Q1 Mar-31-2025 | C2: 3 months Q2 Jun-30-2025 | D2: 3 months Q3 Sep-30-2025 | E2: 3 months Q4 Dec-31-2025 | F2: 3 months Q1 Mar-31-2026 | G2: 3 months Q2 Jun-30-2026
A3: Currency | B3: USD | C3: USD | D3: USD | E3: USD | F3: USD | G3: USD
A5: Revenue | B5: 98.642 | C5: 107.133 | D5: 109.653 | E5: 118.909 | F5: 127.434 | G5: 135.707
A6: Other Revenue | B6: - | C6: - | D6: - | E6: - | F6: - | G6: -
A7: Total Revenue | B7: 98.642 | C7: 107.133 | D7: 109.653 | E7: 118.909 | F7: 127.434 | G7: 135.707
A9: Cost Of Goods Sold | B9: 58.832 | C9: 65.182 | D9: 66.567 | E9: 71.953 | F9: 77.379 | G9: 80.101
A10: Gross Profit | B10: 39.81 | C10: 41.951 | D10: 43.086 | E10: 46.956 | F10: 50.055 | G10: 55.606
A12: Selling General & Admin Exp. | B12: 35.688 | C12: 35.324 | D12: 38.846 | E12: 45.347 | F12: 49.111 | G12: 51.252
A13: R & D Exp. | B13: 21.346 | C13: 22.737 | D13: 23.131 | E13: 25.089 | F13: 24.528 | G13: 26.108
A14: Depreciation & Amort. | B14: - | C14: - | D14: - | E14: - | F14: - | G14: -
A15: Other Operating Expense/(Income) | B15: - | C15: - | D15: - | E15: 0.911 | F15: - | G15: -
A17: Other Operating Exp., Total | B17: 57.034 | C17: 58.061 | D17: 61.977 | E17: 71.347 | F17: 73.639 | G17: 77.36
A19: Operating Income | B19: -17.2 | C19: -16.1 | D19: -18.9 | E19: -24.4 | F19: -23.6 | G19: -21.8
A21: Interest Expense | B21: -2.4 | C21: -2.4 | D21: -2.1 | E21: -0.4 | F21: -0.2 | G21: -0.3
A22: Interest and Invest. Income | B22: 0.567 | C22: 0.487 | D22: 0.883 | E22: 3.335 | F22: 2.779 | G22: 2.799
A23: Net Interest Exp. | B23: -1.8 | C23: -1.9 | D23: -1.3 | E23: 2.964 | F23: 2.55 | G23: 2.517
A25: Currency Exchange Gains (Loss) | B25: 0.408 | C25: 0.661 | D25: -0.3 | E25: -0.3 | F25: -0.5 | G25: -0.3
A26: Other Non-Operating Inc. (Exp.) | B26: 1.299 | C26: -3 | D26: -5.4 | E26: -0.1 | F26: 0.135 | G26: 0.124
A27: EBT Excl. Unusual Items | B27: -17.4 | C27: -20.3 | D27: -25.9 | E27: -21.8 | F27: -21.4 | G27: -19.4
A29: Impairment of Goodwill | B29: - | C29: - | D29: - | E29: - | F29: - | G29: -
A30: Other Unusual Items | B30: 1.811 | C30: - | D30: -10.5 | E30: 0.231 | F30: 1.758 | G30: -
A31: EBT Incl. Unusual Items | B31: -15.5 | C31: -20.3 | D31: -36.4 | E31: -21.5 | F31: -19.6 | G31: -19.4
A33: Income Tax Expense | B33: 0.772 | C33: 0.872 | D33: 0.49 | E33: 0.387 | F33: 0.557 | G33: 0.165
A34: Earnings from Cont. Ops. | B34: -16.3 | C34: -21.2 | D34: -36.9 | E34: -21.9 | F34: -20.1 | G34: -19.6
A36: Earnings of Discontinued Ops. | B36: - | C36: - | D36: - | E36: - | F36: - | G36: -
A37: Extraord. Item & Account. Change | B37: - | C37: - | D37: - | E37: - | F37: - | G37: -
A38: Net Income to Company | B38: -16.3 | C38: -21.2 | D38: -36.9 | E38: -21.9 | F38: -20.1 | G38: -19.6
A40: Minority Int. in Earnings | B40: - | C40: - | D40: - | E40: - | F40: - | G40: -
A41: Net Income | B41: -16.3 | C41: -21.2 | D41: -36.9 | E41: -21.9 | F41: -20.1 | G41: -19.6
A43: Pref. Dividends and Other Adj. | B43: - | C43: - | D43: - | E43: - | F43: - | G43: -
A45: NI to Common Incl Extra Items | B45: -16.3 | C45: -21.2 | D45: -36.9 | E45: -21.9 | F45: -20.1 | G45: -19.6
A46: NI to Common Excl. Extra Items | B46: -16.3 | C46: -21.2 | D46: -36.9 | E46: -21.9 | F46: -20.1 | G46: -19.6
A48: Per Share Items
A49: Basic EPS | B49: -1.28 | C49: -1.66 | D49: -1.49 | E49: -0.27 | F49: -0.25 | G49: -0.24
A50: Basic EPS Excl. Extra Items | B50: -1.28 | C50: -1.66 | D50: -1.49 | E50: -0.27 | F50: -0.25 | G50: -0.24
A51: Weighted Avg. Basic Shares Out. | B51: 12.753056 | C51: 12.793403 | D51: 24.730353 | E51: 81.349711 | F51: 81.177074 | G51: 81.337205
A53: Diluted EPS | B53: -1.28 | C53: -1.66 | D53: -1.49 | E53: -0.27 | F53: -0.25 | G53: -0.24
A54: Diluted EPS Excl. Extra Items | B54: -1.28 | C54: -1.66 | D54: -1.49 | E54: -0.27 | F54: -0.25 | G54: -0.24
A55: Weighted Avg. Diluted Shares Out. | B55: 12.753056 | C55: 12.793403 | D55: 24.730353 | E55: 81.349711 | F55: 81.177074 | G55: 81.337205
...

Sheet BS
A1: Balance Sheet
A2: Balance Sheet as of: | B2: Q1 Mar-31-2025 | C2: Q2 Jun-30-2025 | D2: Q3 Sep-30-2025 | E2: Q4 Dec-31-2025 | F2: Q1 Mar-31-2026 | G2: Q2 Jun-30-2026
A3: Currency | B3: USD | C3: USD | D3: USD | E3: USD | F3: USD | G3: USD
A4: ASSETS
A5: Cash And Equivalents | B5: - | C5: 78.212 | D5: 378.158 | E5: 370.914 | F5: 348.158 | G5: 335.915
A6: Total Cash & ST Investments | B6: 77.905 | C6: 78.212 | D6: 378.158 | E6: 370.914 | F6: 348.158 | G6: 335.915
A8: Accounts Receivable | B8: - | C8: 82.228 | D8: 84.307 | E8: 81.572 | F8: 94.916 | G8: 104.679
A9: Total Receivables | B9: - | C9: 82.228 | D9: 84.307 | E9: 81.572 | F9: 94.916 | G9: 104.679
A11: Prepaid Exp. | B11: - | C11: 12.19 | D11: 15.641 | E11: 16.265 | F11: 17.204 | G11: 16.812
A12: Other Current Assets | B12: - | C12: 0.9 | D12: 0.8 | E12: 0.8 | F12: 0.9 | G12: 0.8
A13: Total Current Assets | B13: - | C13: 173.53 | D13: 478.906 | E13: 469.551 | F13: 461.178 | G13: 458.206
A15: Gross Property, Plant & Equipment | B15: - | C15: 44.389 | D15: 44.638 | E15: 47.997 | F15: 50.603 | G15: 51.203
A16: Accumulated Depreciation | B16: - | C16: -14.5 | D16: -15.4 | E16: -16.3 | F16: -17.1 | G16: -18.1
A17: Net Property, Plant & Equipment | B17: - | C17: 29.865 | D17: 29.254 | E17: 31.714 | F17: 33.459 | G17: 33.136
A19: Goodwill | B19: - | C19: 167.011 | D19: 165.962 | E19: 192.305 | F19: 191.005 | G19: 190.72
A20: Other Intangibles | B20: - | C20: 25.521 | D20: 24.127 | E20: 36.025 | F20: 34.336 | G20: 32.971
A21: Deferred Tax Assets, LT | B21: - | C21: 0.361 | D21: 1.183 | E21: 0.529 | F21: 0.437 | G21: 0.401
A22: Deferred Charges, LT | B22: - | C22: 0.8 | D22: 0.8 | E22: 0.7 | F22: 0.6 | G22: 0.6
... A24: Total Assets | B24: - | C24: 398.87 | D24: 702.058 | E24: 733.095 | F24: 723.32 | G24: 718.349
A26: LIABILITIES
A27: Accounts Payable | B27: - | C27: 6.9 | D27: 5.663 | E27: 4.427 | F27: 7.222 | G27: 6.039
A28: Accrued Exp. | B28: - | C28: 44.954 | D28: 50.169 | E28: 51.546 | F28: 47.694 | G28: 50.76
A29: Curr. Port. of Leases | B29: - | C29: 7.954 | D29: 8.106 | E29: 9.749 | F29: 10.021 | G29: 9.829
A30: Curr. Income Taxes Payable | B30: - | C30: 1.746 | D30: 1.345 | E30: 1.62 | F30: 1.733 | G30: 1.358
A31: Unearned Revenue, Current | B31: - | C31: 21.26 | D31: 24.103 | E31: 26.893 | F31: 23.954 | G31: 22.81
A32: Other Current Liabilities | B32: - | C32: - | D32: 3.319 | E32: - | F32: - | G32: -
A33: Total Current Liabilities | B33: - | C33: 82.814 | D33: 92.705 | E33: 94.235 | F33: 90.624 | G33: 90.796
A35: Long-Term Debt | B35: - | C35: 70.881 | D35: 25 | E35: - | F35: - | G35: -
A36: Long-Term Leases | B36: - | C36: 9.602 | D36: 8.409 | E36: 9.378 | F36: 9.249 | G36: 8.196
A37: Unearned Revenue, Non-Current | B37: - | C37: 1.499 | D37: 1.354 | E37: 1.746 | F37: 1.321 | G37: 1.048
A38: Other Non-Current Liabilities | B38: - | C38: 17.675 | D38: - | E38: - | F38: - | G38: -
A39: Total Liabilities | B39: - | C39: 182.471 | D39: 127.468 | E39: 105.359 | F39: 101.194 | G39: 100.04
A41: Pref. Stock, Convertible | B41: - | C41: 1220.005 | D41: - | E41: - | F41: - | G41: -
A42: Total Pref. Equity | B42: 1195.058 | C42: 1220.005 | D42: - | E42: - | F42: - | G42: -
A44: Common Stock | B44: - | C44: - | D44: 0.001 | E44: 0.001 | F44: 0.001 | G44: 0.001
A45: Additional Paid In Capital | B45: - | C45: 120.091 | D45: 1736.317 | E45: 1811.349 | F45: 1827.909 | G45: 1844.614
A46: Retained Earnings | B46: - | C46: -1132.5 | D46: -1169.4 | E46: -1191.3 | F46: -1211.5 | G46: -1231
A47: Treasury Stock | B47: - | C47: - | D47: - | E47: - | F47: - | G47: -
A48: Comprehensive Inc. and Other | B48: - | C48: 8.796 | D48: 7.652 | E48: 7.702 | F48: 5.681 | G48: 4.715
A49: Total Common Equity | B49: -987.1 | C49: -1003.6 | D49: 574.59 | E49: 627.736 | F49: 622.126 | G49: 618.309
...

Sheet CFS
A1: Cash Flow
A2: For the Fiscal Period Ending | B2: 3 months Q1 Mar-31-2025 | C2: 3 months Q2 Jun-30-2025 | D2: 3 months Q3 Sep-30-2025 | E2: 3 months Q4 Dec-31-2025 | F2: 3 months Q1 Mar-31-2026 | G2: 3 months Q2 Jun-30-2026
A3: Currency | B3: USD | C3: USD | D3: USD | E3: USD | F3: USD | G3: USD
A5: Net Income | B5: -16.3 | C5: -21.2 | D5: -36.9 | E5: -21.9 | F5: -20.1 | G5: -19.6
A6: Depreciation & Amort. | B6: 0.983 | C6: 0.906 | D6: 1.014 | E6: 0.968 | F6: 0.987 | G6: 1
A7: Amort. of Goodwill and Intangibles | B7: 1.299 | C7: 1.155 | D7: 1.119 | E7: 1.085 | F7: 1.412 | G7: 1.38
A8: Depreciation & Amort., Total | B8: 2.282 | C8: 2.061 | D8: 2.133 | E8: 2.053 | F8: 2.399 | G8: 2.38
A10: Other Amortization | B10: 1.618 | C10: 1.71 | D10: 1.491 | E10: 0 | F10: - | G10: -
A11: Stock-Based Compensation | B11: 4.691 | C11: 4.662 | D11: 6.592 | E11: 14.396 | F11: 15.564 | G11: 16.01
A12: Other Operating Activities | B12: 0.708 | C12: 5.237 | D12: 17.7 | E12: 3.264 | F12: 3.376 | G12: 2.853
A13: Change in Acc. Receivable | B13: -0.5 | C13: -5.8 | D13: -2.1 | E13: 6.615 | F13: -13.8 | G13: -9.9
A14: Change in Acc. Payable | B14: 2.455 | C14: 0.365 | D14: -1.3 | E14: -1.9 | F14: 2.818 | G14: -1.2
A15: Change in Unearned Rev. | B15: -1 | C15: -1.6 | D15: 2.672 | E15: 0.272 | F15: -3.2 | G15: -1.4
A16: Change in Other Net Operating Assets | B16: 0.401 | C16: -1.7 | D16: 1.083 | E16: -3.2 | F16: -8.2 | G16: 0.073
A17: Cash from Ops. | B17: -5.6 | C17: -16.3 | D17: -8.5 | E17: -0.5 | F17: -21.2 | G17: -10.6
A19: Capital Expenditure | B19: -0.4 | C19: -0.6 | D19: -0.4 | E19: -0.3 | F19: -0.3 | G19: -0.4
A20: Cash Acquisitions | B20: - | C20: - | D20: - | E20: -39.9 | F20: - | G20: 0.279
A21: Divestitures | B21: - | C21: - | D21: - | E21: - | F21: - | G21: -
A22: Sale (Purchase) of Intangible assets | B22: -0.9 | C22: -1.2 | D22: -1.1 | E22: -1 | F22: -2 | G22: -2
A23: Invest. in Marketable & Equity Securt. | B23: - | C23: - | D23: - | E23: - | F23: - | G23: -
A24: Net (Inc.) Dec. in Loans Originated/Sold | B24: - | C24: - | D24: - | E24: - | F24: - | G24: -
A25: Other Investing Activities | B25: - | C25: - | D25: - | E25: - | F25: - | G25: -
A26: Cash from Investing | B26: -1.3 | C26: -1.8 | D26: -1.5 | E26: -41.2 | F26: -2.3 | G26: -2.1
A28: Short Term Debt Issued | B28: - | C28: - | D28: - | E28: - | F28: - | G28: -
A29: Long-Term Debt Issued | B29: 7.5 | C29: - | D29: - | E29: - | F29: - | G29: -
A30: Total Debt Issued | B30: 7.5 | C30: 0 | D30: 0 | E30: 0 | F30: - | G30: -
A31: Short Term Debt Repaid | B31: - | C31: - | D31: - | E31: - | F31: - | G31: -
A32: Long-Term Debt Repaid | B32: -5 | C32: - | D32: - | E32: - | F32: - | G32: -
A33: Total Debt Repaid | B33: -5 | C33: 0 | D33: -5 | E33: -25 | F33: - | G33: -
A35: Issuance of Common Stock | B35: 0.68 | C35: 1.374 | D35: 314.718 | E35: 63.388 | F35: 0.996 | G35: 0.695
A36: Issuance of Pref. Stock | B36: 20 | C36: 0 | D36: 0 | E36: 0 | F36: - | G36: -
A38: Total Dividends Paid | B38: - | C38: - | D38: - | E38: - | F38: - | G38: -
A40: Special Dividend Paid | B40: - | C40: - | D40: - | E40: - | F40: - | G40: -
A41: Other Financing Activities | B41: -0.3 | C41: 0 | D41: 0 | E41: -4 | F41: - | G41: -
A42: Cash from Financing | B42: 22.858 | C42: 1.374 | D42: 309.718 | E42: 34.376 | F42: 0.996 | G42: 0.695
A44: Foreign Exchange Rate Adj. | B44: 0.322 | C44: 0.743 | D44: 0.261 | E44: 0.119 | F44: -0.2 | G44: -0.1
A45: Net Change in Cash | B45: 16.324 | C45: -16 | D45: 299.991 | E45: -7.2 | F45: -22.7 | G45: -12.2
A47: Supplemental Items
A48: Cash Interest Paid | B48: 0.796 | C48: 0.642 | D48: 0.811 | E48: 0.529 | F48: NA | G48: 0.41
A49: Cash Taxes Paid | B49: 0.328 | C49: 0.59 | D49: 2.24 | E49: 0.26 | F49: 0.311 | G49: 0.483
...
