Workbook

Sheet Summary
A1: VIA: software vs. services revenue mix
A2: All $ in millions. Blue = hardcoded input; black = formula; green = link to another sheet. Yellow = key assumption to flex.
A4: 1) Mix implied by the financials (Q2 2026)
A5: Services cost intensity (tech-enabled services cost / revenue) | B5: =Margin_Decomp!I22 -> 0.51436993 | C5: Hard floor on services share if services earn a 0% gross margin.
A6: Services share at base-case services GM | B6: =Margin_Decomp!I16 -> 0.69204316 | C6: Base services GM set on Margin_Decomp!C5.
A7: Implied software GM at base case | B7: =Margin_Decomp!I19 -> 0.83608418 | C7: Check that it's plausible (typically 70–85% for vertical SaaS).
A8: Services GM needed to reproduce Bleecker's 72% | B8: =Margin_Decomp!I25 -> 0.25028658 | C8: Compare with contract operators (Transdev, MV), which run low-teens gross margins.
A9: Your formula: (gS − g)/(gS − gV) at 80% / 25% | B9: =Blended_Formula!C8 -> 0.70958666 | C9: Uses Q2'26 reported GM.
A11: 2) Contract-based mix (Bleecker method + contracts since Dec 16, 2025)
A12: Bleecker baseline services share (Dec 2025) | B12: =Updated_Mix!C6 -> 0.72 | C12: Bleecker's headline estimate. Their contract table couldn't be accessed from here.
A13: Scenario A: + identified public contracts | B13: =Updated_Mix!D24 -> 0.72647851 | C13: Only contracts with a public $ value and a clear scope.
A14: Scenario B: A + mgmt's '4 network deals, >$40M ACV' | B14: =Updated_Mix!D33 -> 0.74083711 | C14: Swaps possible-network deals (Plano, TCATA) for mgmt's $40M total.
A15: Scenario C: rolled forward to Q2'26 ARR | B15: =Updated_Mix!D44 -> 0.74003073 | C15: Leftover growth taken at the input share on Updated_Mix!C40.
A17: Read-across
A18: • The financials support Bleecker's 72% only if Via earns ~25% gross margin on services (implied software GM ~82%). At 20% services GM the Q2'26 mix is ~67.5% services; at 15%, ~63.5%. If insurance is outside COGS as Bleecker says (Margin_Decomp!C7), the services share goes up.
A19: • Tech-enabled services cost rose from 49.7% of revenue (FY2024) to 51–52% (FY2025–Q2'26). The financials show no shift toward software yet. The Q2'26 GM step-up came from one-time revenue, which mgmt says will revert.
A20: • Every new contract found with a public $ value since Dec 2025 is turnkey (~96% services by line item). The only software-only deal found is NJ TRANSIT Monmouth, value undisclosed. The contract-based mix drifts up to ~72.7% (A) and ~74% (B/C).
A21: • Caveat: public records over-sample large turnkey deals, because small software-only renewals often fall below council approval thresholds or run through co-op contracts (OMNIA). That biases the contract method toward services.

Sheet Margin_Inputs
A1: Reported revenue and cost-of-revenue split ($mm, GAAP)
A2: Via splits cost of revenue into: technology-enabled services (drivers, vehicles, fleet mgmt, call center), launch & support personnel, IT & other (hosting, amortization).
A4: Period | B4: Revenue | C4: Tech-enabled services cost | D4: Launch & support personnel | E4: IT & other | F4: Total COGS | G4: Gross profit | H4: GM % | I4: Source / note
A5: FY2024 | B5: 337.6 | C5: 167.7 | D5: 24.3 | E5: 14.8 | F5: =C5+D5+E5 -> 206.8 | G5: =B5-F5 -> 130.8 | H5: =IF(B5=0,0,G5/B5) -> 0.38744076 | I5: S-1/A: FY24 revenue $337.6M; cost split $167.7 / $24.3 / $14.8M (total $206.8M).
A6: H1 2025 | B6: 205.775 | C6: 105 | D6: 12.3 | E6: 6.7 | F6: =C6+D6+E6 -> 124 | G6: =B6-F6 -> 81.775 | H6: =IF(B6=0,0,G6/B6) -> 0.39740007 | I6: Q3'25 10-Q: 6M revenue = GP $81.761M + COGS $124.014M; cost split $105.0 / $12.3 / $6.7M.
A7: Q3 2025 | B7: 109.653 | C7: 57.1 | D7: 6.3 | E7: 3.2 | F7: =C7+D7+E7 -> 66.6 | G7: =B7-F7 -> 43.053 | H7: =IF(B7=0,0,G7/B7) -> 0.39262948 | I7: Q3'25 10-Q: revenue $109.653M, GP $43.086M; cost split $57.1 / $6.3 / $3.2M.
A8: Q4 2025 | B8: =B9-B6-B7 -> 118.909 | C8: =C9-C6-C7 -> 61.4 | D8: =D9-D6-D7 -> 7.2 | E8: =E9-E6-E7 -> 3.4 | F8: =C8+D8+E8 -> 72 | G8: =B8-F8 -> 46.909 | H8: =IF(B8=0,0,G8/B8) -> 0.39449495 | I8: Derived: FY2025 − H1 2025 − Q3 2025.
A9: FY2025 | B9: 434.337 | C9: 223.5 | D9: 25.8 | E9: 13.3 | F9: =C9+D9+E9 -> 262.6 | G9: =B9-F9 -> 171.737 | H9: =IF(B9=0,0,G9/B9) -> 0.39540035 | I9: 10-K FY25: revenue $434.337M; cost split $223.5 / $25.8 / $13.3M.
A10: Q1 2026 | B10: 127.43 | C10: 66.8 | D10: 7.3 | E10: 3.3 | F10: =C10+D10+E10 -> 77.4 | G10: =B10-F10 -> 50.03 | H10: =IF(B10=0,0,G10/B10) -> 0.39260771 | I10: Q1'26 10-Q: revenue $127.43M; COGS $77.4M; GP $50.1M.
A11: Q2 2026 | B11: 135.7 | C11: 69.8 | D11: 6.9 | E11: 3.4 | F11: =C11+D11+E11 -> 80.1 | G11: =B11-F11 -> 55.6 | H11: =IF(B11=0,0,G11/B11) -> 0.40972734 | I11: Q2'26 10-Q: COGS $80.1M, GP $55.6M (so revenue = $135.7M).
A13: Check: Q2'26 COGS | B13: 80.1 | C13: =F11-B13 -> 0 | D13: ← should be ~0 (rounding)
A14: Check: Q1'26 COGS | B14: 77.4 | C14: =F10-B14 -> 0
A15: Check: Q3'25 COGS | B15: 66.567 | C15: =F7-B15 -> 0.033
A17: Adjusted GM (non-GAAP, excludes SBC and acquired-intangible amortization) is within ~0.5pt of GAAP (e.g. Q3'25 adj. GP $43.471M vs GAAP $43.086M), so GAAP is used throughout. Mgmt: Q2'26 adj. GM 41%, LT target 50%.

Sheet Margin_Decomp
B1: Backing out the mix from the cost-of-revenue split
B2: Services revenue = services cost / (1 − services GM). Software revenue = revenue − services revenue. Implied software GM follows. If implied software GM comes out implausible, the services GM assumption is wrong.
B4: Assumptions
B5: Services gross margin (gV) | C5: 0.22
B6: Share of launch & support personnel allocated to services (α) | C6: 0.5
B7: Insurance outside COGS, % of revenue (Bleecker claim) | C7: 0
B8: Bleecker services share (target to reconcile) | C8: 0.72
B10: Line | C10: FY2024 | D10: H1 2025 | E10: Q3 2025 | F10: Q4 2025 | G10: FY2025 | H10: Q1 2026 | I10: Q2 2026
B11: Revenue | C11: =Margin_Inputs!B5 -> 337.6 | D11: =Margin_Inputs!B6 -> 205.775 | E11: =Margin_Inputs!B7 -> 109.653 | F11: =Margin_Inputs!B8 -> 118.909 | G11: =Margin_Inputs!B9 -> 434.337 | H11: =Margin_Inputs!B10 -> 127.43 | I11: =Margin_Inputs!B11 -> 135.7
B12: Tech-enabled services cost | C12: =Margin_Inputs!C5 -> 167.7 | D12: =Margin_Inputs!C6 -> 105 | E12: =Margin_Inputs!C7 -> 57.1 | F12: =Margin_Inputs!C8 -> 61.4 | G12: =Margin_Inputs!C9 -> 223.5 | H12: =Margin_Inputs!C10 -> 66.8 | I12: =Margin_Inputs!C11 -> 69.8
B13: Services cost incl. α·LSP + insurance | C13: =C12+$C$6*Margin_Inputs!D5+$C$7*C11 -> 179.85 | D13: =D12+$C$6*Margin_Inputs!D6+$C$7*D11 -> 111.15 | E13: =E12+$C$6*Margin_Inputs!D7+$C$7*E11 -> 60.25 | F13: =F12+$C$6*Margin_Inputs!D8+$C$7*F11 -> 65 | G13: =G12+$C$6*Margin_Inputs!D9+$C$7*G11 -> 236.4 | H13: =H12+$C$6*Margin_Inputs!D10+$C$7*H11 -> 70.45 | I13: =I12+$C$6*Margin_Inputs!D11+$C$7*I11 -> 73.25
B14: Software cost = IT&other + (1−α)·LSP | C14: =Margin_Inputs!E5+(1-$C$6)*Margin_Inputs!D5 -> 26.95 | D14: =Margin_Inputs!E6+(1-$C$6)*Margin_Inputs!D6 -> 12.85 | E14: =Margin_Inputs!E7+(1-$C$6)*Margin_Inputs!D7 -> 6.35 | F14: =Margin_Inputs!E8+(1-$C$6)*Margin_Inputs!D8 -> 7 | G14: =Margin_Inputs!E9+(1-$C$6)*Margin_Inputs!D9 -> 26.2 | H14: =Margin_Inputs!E10+(1-$C$6)*Margin_Inputs!D10 -> 6.95 | I14: =Margin_Inputs!E11+(1-$C$6)*Margin_Inputs!D11 -> 6.85
B15: Implied services revenue | C15: =C13/(1-$C$5) -> 230.57692 | D15: =D13/(1-$C$5) -> 142.5 | E15: =E13/(1-$C$5) -> 77.24359 | F15: =F13/(1-$C$5) -> 83.333333 | G15: =G13/(1-$C$5) -> 303.07692 | H15: =H13/(1-$C$5) -> 90.320513 | I15: =I13/(1-$C$5) -> 93.910256
B16: Services share of revenue | C16: =IF(C11=0,0,C15/C11) -> 0.68298852 | D16: =IF(D11=0,0,D15/D11) -> 0.69250395 | E16: =IF(E11=0,0,E15/E11) -> 0.70443663 | F16: =IF(F11=0,0,F15/F11) -> 0.70081603 | G16: =IF(G11=0,0,G15/G11) -> 0.69779209 | H16: =IF(H11=0,0,H15/H11) -> 0.70878532 | I16: =IF(I11=0,0,I15/I11) -> 0.69204316
B17: Implied software revenue | C17: =C11-C15 -> 107.02308 | D17: =D11-D15 -> 63.275 | E17: =E11-E15 -> 32.40941 | F17: =F11-F15 -> 35.575667 | G17: =G11-G15 -> 131.26008 | H17: =H11-H15 -> 37.109487 | I17: =I11-I15 -> 41.789744
B18: Software share of revenue | C18: =1-C16 -> 0.31701148 | D18: =1-D16 -> 0.30749605 | E18: =1-E16 -> 0.29556337 | F18: =1-F16 -> 0.29918397 | G18: =1-G16 -> 0.30220791 | H18: =1-H16 -> 0.29121468 | I18: =1-I16 -> 0.30795684
B19: Implied software GM | C19: =IF(C17<=0,0,(C17-C14)/C17) -> 0.74818515 | D19: =IF(D17<=0,0,(D17-D14)/D17) -> 0.79691821 | E19: =IF(E17<=0,0,(E17-E14)/E17) -> 0.80406925 | F19: =IF(F17<=0,0,(F17-F14)/F17) -> 0.80323629 | G19: =IF(G17<=0,0,(G17-G14)/G17) -> 0.80039628 | H19: =IF(H17<=0,0,(H17-H14)/H17) -> 0.81271636 | I19: =IF(I17<=0,0,(I17-I14)/I17) -> 0.83608418
B20: Blended GM (check vs reported) | C20: =(C11-C13-C14)/C11+$C$7 -> 0.38744076 | D20: =(D11-D13-D14)/D11+$C$7 -> 0.39740007 | E20: =(E11-E13-E14)/E11+$C$7 -> 0.39262948 | F20: =(F11-F13-F14)/F11+$C$7 -> 0.39449495 | G20: =(G11-G13-G14)/G11+$C$7 -> 0.39540035 | H20: =(H11-H13-H14)/H11+$C$7 -> 0.39260771 | I20: =(I11-I13-I14)/I11+$C$7 -> 0.40972734
B22: Services cost intensity: tech-enabled cost / revenue (0%-margin floor) | C22: =C12/C11 -> 0.49674171 | D22: =D12/D11 -> 0.51026607 | E22: =E12/E11 -> 0.52073359 | F22: =F12/F11 -> 0.51636125 | G22: =G12/G11 -> 0.51457739 | H22: =H12/H11 -> 0.52420937 | I22: =I12/I11 -> 0.51436993
B23: Services share if services GM = 15% | C23: =(C13/(1-0.15))/C11 -> 0.6267424 | D23: =(D13/(1-0.15))/D11 -> 0.63547421 | E23: =(E13/(1-0.15))/E11 -> 0.6464242 | F23: =(F13/(1-0.15))/F11 -> 0.64310177 | G23: =(G13/(1-0.15))/G11 -> 0.64032686 | H23: =(H13/(1-0.15))/H11 -> 0.65041476 | I23: =(I13/(1-0.15))/I11 -> 0.63505137
B24: Services share if services GM = 30% | C24: =(C13/(1-0.3))/C11 -> 0.76104435 | D24: =(D13/(1-0.3))/D11 -> 0.77164726 | E24: =(E13/(1-0.3))/E11 -> 0.78494367 | F24: =(F13/(1-0.3))/F11 -> 0.78090929 | G24: =(G13/(1-0.3))/G11 -> 0.77753976 | H24: =(H13/(1-0.3))/H11 -> 0.78978935 | I24: =(I13/(1-0.3))/I11 -> 0.7711338
B25: Services GM required to hit Bleecker share | C25: =1-C13/($C$8*C11) -> 0.26009577 | D25: =1-D13/($C$8*D11) -> 0.24978739 | E25: =1-E13/($C$8*E11) -> 0.23686032 | F25: =1-F13/($C$8*F11) -> 0.24078263 | G25: =1-G13/($C$8*G11) -> 0.24405857 | H25: =1-H13/($C$8*H11) -> 0.23214924 | I25: =1-I13/($C$8*I11) -> 0.25028658
B26: …and the software GM that implies | C26: =(C11*(1-$C$8)-C14)/(C11*(1-$C$8)) -> 0.71489929 | D26: =(D11*(1-$C$8)-D14)/(D11*(1-$C$8)) -> 0.77697555 | E26: =(E11*(1-$C$8)-E14)/(E11*(1-$C$8)) -> 0.79317874 | F26: =(F11*(1-$C$8)-F14)/(F11*(1-$C$8)) -> 0.78975519 | G26: =(G11*(1-$C$8)-G14)/(G11*(1-$C$8)) -> 0.78456491 | H26: =(H11*(1-$C$8)-H14)/(H11*(1-$C$8)) -> 0.80521519 | I26: =(I11*(1-$C$8)-I14)/(I11*(1-$C$8)) -> 0.81971787
B27: Row 20 should equal the reported GM on Margin_Inputs (insurance is added back because it's being moved into COGS only for the mix calculation).
B30: Sensitivity (Q2 2026): services share of revenue
B31: rows = services GM; cols = α (share of launch & support in services)
B32: gV \ α | C32: 0 | D32: 0.5 | E32: 1
B33: 0.1 | C33: =((Margin_Inputs!$C$11+C$32*Margin_Inputs!$D$11+$C$7*Margin_Inputs!$B$11)/(1-$B33))/Margin_Inputs!$B$11 -> 0.57152215 | D33: =((Margin_Inputs!$C$11+D$32*Margin_Inputs!$D$11+$C$7*Margin_Inputs!$B$11)/(1-$B33))/Margin_Inputs!$B$11 -> 0.59977074 | E33: =((Margin_Inputs!$C$11+E$32*Margin_Inputs!$D$11+$C$7*Margin_Inputs!$B$11)/(1-$B33))/Margin_Inputs!$B$11 -> 0.62801932
B34: 0.15 | C34: =((Margin_Inputs!$C$11+C$32*Margin_Inputs!$D$11+$C$7*Margin_Inputs!$B$11)/(1-$B34))/Margin_Inputs!$B$11 -> 0.6051411 | D34: =((Margin_Inputs!$C$11+D$32*Margin_Inputs!$D$11+$C$7*Margin_Inputs!$B$11)/(1-$B34))/Margin_Inputs!$B$11 -> 0.63505137 | E34: =((Margin_Inputs!$C$11+E$32*Margin_Inputs!$D$11+$C$7*Margin_Inputs!$B$11)/(1-$B34))/Margin_Inputs!$B$11 -> 0.66496164
B35: 0.2 | C35: =((Margin_Inputs!$C$11+C$32*Margin_Inputs!$D$11+$C$7*Margin_Inputs!$B$11)/(1-$B35))/Margin_Inputs!$B$11 -> 0.64296242 | D35: =((Margin_Inputs!$C$11+D$32*Margin_Inputs!$D$11+$C$7*Margin_Inputs!$B$11)/(1-$B35))/Margin_Inputs!$B$11 -> 0.67474208 | E35: =((Margin_Inputs!$C$11+E$32*Margin_Inputs!$D$11+$C$7*Margin_Inputs!$B$11)/(1-$B35))/Margin_Inputs!$B$11 -> 0.70652174
B36: 0.25 | C36: =((Margin_Inputs!$C$11+C$32*Margin_Inputs!$D$11+$C$7*Margin_Inputs!$B$11)/(1-$B36))/Margin_Inputs!$B$11 -> 0.68582658 | D36: =((Margin_Inputs!$C$11+D$32*Margin_Inputs!$D$11+$C$7*Margin_Inputs!$B$11)/(1-$B36))/Margin_Inputs!$B$11 -> 0.71972488 | E36: =((Margin_Inputs!$C$11+E$32*Margin_Inputs!$D$11+$C$7*Margin_Inputs!$B$11)/(1-$B36))/Margin_Inputs!$B$11 -> 0.75362319
B37: 0.3 | C37: =((Margin_Inputs!$C$11+C$32*Margin_Inputs!$D$11+$C$7*Margin_Inputs!$B$11)/(1-$B37))/Margin_Inputs!$B$11 -> 0.73481419 | D37: =((Margin_Inputs!$C$11+D$32*Margin_Inputs!$D$11+$C$7*Margin_Inputs!$B$11)/(1-$B37))/Margin_Inputs!$B$11 -> 0.7711338 | E37: =((Margin_Inputs!$C$11+E$32*Margin_Inputs!$D$11+$C$7*Margin_Inputs!$B$11)/(1-$B37))/Margin_Inputs!$B$11 -> 0.80745342
B38: 0.35 | C38: =((Margin_Inputs!$C$11+C$32*Margin_Inputs!$D$11+$C$7*Margin_Inputs!$B$11)/(1-$B38))/Margin_Inputs!$B$11 -> 0.79133836 | D38: =((Margin_Inputs!$C$11+D$32*Margin_Inputs!$D$11+$C$7*Margin_Inputs!$B$11)/(1-$B38))/Margin_Inputs!$B$11 -> 0.83045179 | E38: =((Margin_Inputs!$C$11+E$32*Margin_Inputs!$D$11+$C$7*Margin_Inputs!$B$11)/(1-$B38))/Margin_Inputs!$B$11 -> 0.86956522
B40: Sensitivity (Q2 2026): implied software GM
B41: gV \ α | C41: 0 | D41: 0.5 | E41: 1
B42: 0.1 | C42: =IF((Margin_Inputs!$B$11*(1-C33))<=0,0,((Margin_Inputs!$B$11*(1-C33))-(Margin_Inputs!$E$11+(1-C$41)*Margin_Inputs!$D$11))/(Margin_Inputs!$B$11*(1-C33))) -> 0.82285496 | D42: =IF((Margin_Inputs!$B$11*(1-D33))<=0,0,((Margin_Inputs!$B$11*(1-D33))-(Margin_Inputs!$E$11+(1-D$41)*Margin_Inputs!$D$11))/(Margin_Inputs!$B$11*(1-D33))) -> 0.8738748 | E42: =IF((Margin_Inputs!$B$11*(1-E33))<=0,0,((Margin_Inputs!$B$11*(1-E33))-(Margin_Inputs!$E$11+(1-E$41)*Margin_Inputs!$D$11))/(Margin_Inputs!$B$11*(1-E33))) -> 0.93264363
B43: 0.15 | C43: =IF((Margin_Inputs!$B$11*(1-C34))<=0,0,((Margin_Inputs!$B$11*(1-C34))-(Margin_Inputs!$E$11+(1-C$41)*Margin_Inputs!$D$11))/(Margin_Inputs!$B$11*(1-C34))) -> 0.80777253 | D43: =IF((Margin_Inputs!$B$11*(1-D34))<=0,0,((Margin_Inputs!$B$11*(1-D34))-(Margin_Inputs!$E$11+(1-D$41)*Margin_Inputs!$D$11))/(Margin_Inputs!$B$11*(1-D34))) -> 0.86168191 | E43: =IF((Margin_Inputs!$B$11*(1-E34))<=0,0,((Margin_Inputs!$B$11*(1-E34))-(Margin_Inputs!$E$11+(1-E$41)*Margin_Inputs!$D$11))/(Margin_Inputs!$B$11*(1-E34))) -> 0.92521672
B44: 0.2 | C44: =IF((Margin_Inputs!$B$11*(1-C35))<=0,0,((Margin_Inputs!$B$11*(1-C35))-(Margin_Inputs!$E$11+(1-C$41)*Margin_Inputs!$D$11))/(Margin_Inputs!$B$11*(1-C35))) -> 0.7874097 | D44: =IF((Margin_Inputs!$B$11*(1-D35))<=0,0,((Margin_Inputs!$B$11*(1-D35))-(Margin_Inputs!$E$11+(1-D$41)*Margin_Inputs!$D$11))/(Margin_Inputs!$B$11*(1-D35))) -> 0.84480317 | E44: =IF((Margin_Inputs!$B$11*(1-E35))<=0,0,((Margin_Inputs!$B$11*(1-E35))-(Margin_Inputs!$E$11+(1-E$41)*Margin_Inputs!$D$11))/(Margin_Inputs!$B$11*(1-E35))) -> 0.91462649
B45: 0.25 | C45: =IF((Margin_Inputs!$B$11*(1-C36))<=0,0,((Margin_Inputs!$B$11*(1-C36))-(Margin_Inputs!$E$11+(1-C$41)*Margin_Inputs!$D$11))/(Margin_Inputs!$B$11*(1-C36))) -> 0.758405 | D45: =IF((Margin_Inputs!$B$11*(1-D36))<=0,0,((Margin_Inputs!$B$11*(1-D36))-(Margin_Inputs!$E$11+(1-D$41)*Margin_Inputs!$D$11))/(Margin_Inputs!$B$11*(1-D36))) -> 0.81989483 | E45: =IF((Margin_Inputs!$B$11*(1-E36))<=0,0,((Margin_Inputs!$B$11*(1-E36))-(Margin_Inputs!$E$11+(1-E$41)*Margin_Inputs!$D$11))/(Margin_Inputs!$B$11*(1-E36))) -> 0.89830508
B46: 0.3 | C46: =IF((Margin_Inputs!$B$11*(1-C37))<=0,0,((Margin_Inputs!$B$11*(1-C37))-(Margin_Inputs!$E$11+(1-C$41)*Margin_Inputs!$D$11))/(Margin_Inputs!$B$11*(1-C37))) -> 0.71377531 | D46: =IF((Margin_Inputs!$B$11*(1-D37))<=0,0,((Margin_Inputs!$B$11*(1-D37))-(Margin_Inputs!$E$11+(1-D$41)*Margin_Inputs!$D$11))/(Margin_Inputs!$B$11*(1-D37))) -> 0.77943882 | E46: =IF((Margin_Inputs!$B$11*(1-E37))<=0,0,((Margin_Inputs!$B$11*(1-E37))-(Margin_Inputs!$E$11+(1-E$41)*Margin_Inputs!$D$11))/(Margin_Inputs!$B$11*(1-E37))) -> 0.86987425
...

Sheet Blended_Formula
B1: Your formula: services share = (gS − g) / (gS − gV)
B3: Blended GM used (g) | C3: =Margin_Inputs!H11 -> 0.40972734 | D3: ← Q2'26 reported. Overwrite with 0.393 for Q1'26/Q3'25.
B4: Software GM (gS) | C4: 0.8
B5: Services GM (gV) | C5: 0.25
B6: LT target blended GM (mgmt) | C6: 0.5
B8: Services share at inputs above | C8: =(C4-C3)/(C4-C5) -> 0.70958666
B9: Services share needed for 50% GM at same gS/gV | C9: =(C4-C6)/(C4-C5) -> 0.54545455
B10: …or services GM needed for 50% at today's mix | C10: =(C6-(1-C8)*C4)/C8 -> 0.37721866
B12: Grid: services share (rows = gS, cols = gV), at blended g in C3
B13: gS \ gV | C13: 0.15 | D13: 0.2 | E13: 0.25 | F13: 0.3 | G13: 0.35
B14: 0.7 | C14: =($B14-$C$3)/($B14-C$13) -> 0.52776847 | D14: =($B14-$C$3)/($B14-D$13) -> 0.58054532 | E14: =($B14-$C$3)/($B14-E$13) -> 0.64505036 | F14: =($B14-$C$3)/($B14-F$13) -> 0.72568165 | G14: =($B14-$C$3)/($B14-G$13) -> 0.82935046
B15: 0.75 | C15: =($B15-$C$3)/($B15-C$13) -> 0.5671211 | D15: =($B15-$C$3)/($B15-D$13) -> 0.61867756 | E15: =($B15-$C$3)/($B15-E$13) -> 0.68054532 | F15: =($B15-$C$3)/($B15-F$13) -> 0.75616147 | G15: =($B15-$C$3)/($B15-G$13) -> 0.85068165
B16: 0.8 | C16: =($B16-$C$3)/($B16-C$13) -> 0.60041948 | D16: =($B16-$C$3)/($B16-D$13) -> 0.65045443 | E16: =($B16-$C$3)/($B16-E$13) -> 0.70958666 | F16: =($B16-$C$3)/($B16-F$13) -> 0.78054532 | G16: =($B16-$C$3)/($B16-G$13) -> 0.86727258
B17: 0.85 | C17: =($B17-$C$3)/($B17-C$13) -> 0.62896094 | D17: =($B17-$C$3)/($B17-D$13) -> 0.67734255 | E17: =($B17-$C$3)/($B17-E$13) -> 0.73378777 | F17: =($B17-$C$3)/($B17-F$13) -> 0.80049575 | G17: =($B17-$C$3)/($B17-G$13) -> 0.88054532
B19: Limitation: blended GM alone can't separate a high services share at good margins from a lower share at poor margins. Margin_Decomp adds the second equation (the reported cost split), which pins down the trade-off.

Sheet Contracts
A1: Contract tracker: Bleecker reference set (pre-Dec 16, 2025) + new contracts since
A2: Software % column: 'Actual' = from contract line items; 'Assumed' = links to the turnkey software-share assumption on Updated_Mix!C8 (Bleecker: software <5% of TCV on turnkey deals). Include = 1 only for post-window contracts with a public $ value that were actually approved.
A4: # | B4: Agency / customer | C4: Via entity | D4: Approved / effective | E4: Window | F4: Scope | G4: Total value ($mm) | H4: Term (months) | I4: Annualized value ($mm) | J4: Software % of value | K4: Software $ (annual) | L4: Services $ (annual) | M4: Line-item basis | N4: Include in update (1/0) | O4: Possible network deal (1/0) | P4: Notes | Q4: Source
A5: 1 | B5: LA Metro – Metro Micro ops (North+South) | C5: Nomad Transit LLC | D5: 2024-11-21 | E5: Pre | F5: Turnkey | G5: 135 | H5: 72 | I5: =IF(H5=0,0,G5/H5*12) -> 22.5 | J5: 0 | K5: =I5*J5 -> 0 | L5: =I5-K5 -> 22.5 | M5: Actual | N5: 0 | O5: 0 | P5: IDIQ, 3+3 yrs; $82.35→$94.50/rev. hr on 253,003 hrs. Software went to Spare Labs ($61K→$447K). Via kept operations only. | Q5: S24,S26
A6: 2 | B6: Arlington, TX – On-Demand | C6: Via | D6: 2024-12 | E6: Pre | F6: Turnkey | G6: 20.7 | H6: 24 | I6: =IF(H6=0,0,G6/H6*12) -> 10.35 | J6: 0.04 | K6: =I6*J6 -> 0.414 | L6: =I6-K6 -> 9.936 | M6: Actual | N6: 0 | O6: 0 | P6: Ceiling cut 31% from $30.2M. 'Micro TaaS' ~96% of value; software <5% and doesn't scale with usage. | Q6: S8,S26
A7: 3 | B7: DCTA GoZone (2023–24 extension) | C7: Via | D7: 2023 | E7: Pre | F7: Turnkey | G7: 10.46 | H7: 12 | I7: =IF(H7=0,0,G7/H7*12) -> 10.46 | J7: 0 | K7: =I7*J7 -> 0 | L7: =I7-K7 -> 10.46 | M7: Actual | N7: 0 | O7: 0 | P7: 234,895 van hrs @ ~$42.11/hr + customer service $283.5K per 6 months. All hour/labor-based. Status after 9/30/24 unverified. | Q7: S26
A8: 4 | B8: King County Metro – Metro Flex | C8: Via | D8: 2023-02 | E8: Pre | F8: Turnkey | G8: 21 | H8: 36 | I8: =IF(H8=0,0,G8/H8*12) -> 7 | J8: =Updated_Mix!$C$8 -> 0.04 | K8: =I8*J8 -> 0.28 | L8: =I8-K8 -> 6.72 | M8: Assumed | N8: 0 | O8: 0 | P8: ~$7M/yr, 3-yr term. Issaquah recommended not renewing its piece at end-2025 (~$41/ride). | Q8: S26
A9: 5 | B9: Mobile, AL – The Wave (full system) | C9: Port City Transit LLC | D9: 2025-09-16 | E9: Pre | F9: Turnkey | G9: 36.3 | H9: 36 | I9: =IF(H9=0,0,G9/H9*12) -> 12.1 | J9: =Updated_Mix!$C$8 -> 0.04 | K9: =I9*J9 -> 0.484 | L9: =I9-K9 -> 11.616 | M9: Assumed | N9: 0 | O9: 1 | P9: $12.1M/yr, 3 yrs + two 1-yr options. Takeover from Transdev, staff transfer. A network deal. | Q9: S26
A10: 6 | B10: New Braunfels, TX | C10: River North Transit LLC | D10: 2025-10-13 | E10: Pre | F10: Turnkey | G10: 6.08 | H10: 60 | I10: =IF(H10=0,0,G10/H10*12) -> 1.216 | J10: =Updated_Mix!$C$8 -> 0.04 | K10: =I10*J10 -> 0.04864 | L10: =I10-K10 -> 1.16736 | M10: Assumed | N10: 0 | O10: 0 | P10: $1.15–1.29M/yr; yr-1 funded mostly by ARPA. | Q10: S26
A11: 7 | B11: Miami-Dade | C11: River North Transit LLC | D11: 2020 | E11: Pre | F11: Turnkey | G11: 4.66 | H11: 36 | I11: =IF(H11=0,0,G11/H11*12) -> 1.5533333 | J11: =Updated_Mix!$C$8 -> 0.04 | K11: =I11*J11 -> 0.062133333 | L11: =I11-K11 -> 1.4912 | M11: Assumed | N11: 0 | O11: 0 | P11: Up to $4.66M over 3 yrs; 45 vehicles as of late 2024. | Q11: S26
A12: 8 | B12: Lorain County, OH – ViaLC extension | C12: River North Transit LLC | D12: 2025-07 | E12: Pre | F12: Turnkey | G12: 2.2 | H12: 12 | I12: =IF(H12=0,0,G12/H12*12) -> 2.2 | J12: =Updated_Mix!$C$8 -> 0.04 | K12: =I12*J12 -> 0.088 | L12: =I12-K12 -> 2.112 | M12: Assumed | N12: 0 | O12: 0 | P12: 1-yr extension through Jul 2026. Jan 2026: $2.8M federal grant to expand (grant, not a contract). | Q12: S23
A13: 9 | B13: Gastonia, NC | C13: River North Transit LLC | D13: 2024 | E13: Pre | F13: Turnkey | G13: 1.65 | H13: 12 | I13: =IF(H13=0,0,G13/H13*12) -> 1.65 | J13: =Updated_Mix!$C$8 -> 0.04 | K13: =I13*J13 -> 0.066 | L13: =I13-K13 -> 1.584 | M13: Assumed | N13: 0 | O13: 0 | P13: $1.65M in yr 1 of 36 months. | Q13: S26
A14: 10 | B14: Q4'25 call example – Texas customer | C14: Via | D14: 2025 | E14: Pre | F14: Turnkey | G14: 3.4 | H14: 36 | I14: =IF(H14=0,0,G14/H14*12) -> 1.1333333 | J14: 0.0044 | K14: =I14*J14 -> 0.0049866667 | L14: =I14-K14 -> 1.1283467 | M14: Actual | N14: 0 | O14: 0 | P14: ~22,000 veh-hrs/yr @ $50/hr = $1.1M ACV; only $15K upfront software implementation (0.44% of TCV). | Q14: S26
A15: 11 | B15: Transport for London – Dial-a-Ride (software) | C15: Via Technologies B.V. | D15: 2022-08-05 | E15: Pre | F15: Software-only | G15: 2.93 | H15: 60 | I15: =IF(H15=0,0,G15/H15*12) -> 0.586 | J15: 1 | K15: =I15*J15 -> 0.586 | L15: =I15-K15 -> 0 | M15: Actual | N15: 0 | O15: 0 | P15: £2,307,950 over 5 yrs (converted at ~$1.27/£). Shows how small software-only ACVs are even at a very large agency. | Q15: S25
A16: 12 | B16: TCATA (Benton Harbor / St. Joseph, MI) | C16: Via | D16: 2025-12 (ops 2026-04-01) | E16: Post | F16: Turnkey (network) | G16: 0 | H16: 12 | I16: =IF(H16=0,0,G16/H16*12) -> 0 | J16: =Updated_Mix!$C$8 -> 0.04 | K16: =I16*J16 -> 0 | L16: =I16-K16 -> 0 | M16: Assumed | N16: 0 | O16: 1 | P16: Board approved Dec 2025; Via took over the whole network Apr 1, 2026. $ value not found in public search. Not in the report (published Dec 16). | Q16: S20
A17: 13 | B17: Plano, TX – Plano Rides | C17: Via Transportation Inc. | D17: 2026-02-23 | E17: Post | F17: Turnkey | G17: 3.952247 | H17: 6 | I17: =IF(H17=0,0,G17/H17*12) -> 7.904494 | J17: =Updated_Mix!$C$8 -> 0.04 | K17: =I17*J17 -> 0.31617976 | L17: =I17-K17 -> 7.5883142 | M17: Assumed | N17: 1 | O17: 1 | P17: $3,952,247 for 6 months; three 1-yr auto renewals est. ~$8M/yr. 22 vehicles, seniors 65+ microtransit + paratransit. | Q17: S11
A18: 14 | B18: Addison, TX – Addison Orbit | C18: Via Transportation Inc. | D18: 2026-03-24 | E18: Post | F18: Turnkey | G18: 0.872231 | H18: 6 | I18: =IF(H18=0,0,G18/H18*12) -> 1.744462 | J18: =Updated_Mix!$C$8 -> 0.04 | K18: =I18*J18 -> 0.06977848 | L18: =I18-K18 -> 1.6746835 | M18: Assumed | N18: 1 | O18: 0 | P18: NTE $872,231, 6-month pilot, microtransit + ADA paratransit, 5am–midnight. | Q18: S12
A19: 15 | B19: NJ TRANSIT MicroLink – Bergen | C19: Via | D19: 2026-04-06 | E19: Post | F19: Turnkey | G19: 0 | H19: 24 | I19: =IF(H19=0,0,G19/H19*12) -> 0 | J19: =Updated_Mix!$C$8 -> 0.04 | K19: =I19*J19 -> 0 | L19: =I19-K19 -> 0 | M19: Assumed | N19: 0 | O19: 0 | P19: Via operates. FTA-funded 2-yr pilot. Value not found. | Q19: S15
A20: 16 | B20: NJ TRANSIT MicroLink – Monmouth | C20: Via | D20: 2026-04-06 | E20: Post | F20: Software-only | G20: 0 | H20: 24 | I20: =IF(H20=0,0,G20/H20*12) -> 0 | J20: 1 | K20: =I20*J20 -> 0 | L20: =I20-K20 -> 0 | M20: Actual | N20: 0 | O20: 0 | P20: NJ TRANSIT runs service itself on Via software. The only software-only deal found in the new window. Value not found. | Q20: S15
A21: 17 | B21: Highland Park, TX – On-Demand | C21: Via | D21: 2026-04 (launch 5/13) | E21: Post | F21: Turnkey | G21: 1.55 | H21: 6 | I21: =IF(H21=0,0,G21/H21*12) -> 3.1 | J21: =Updated_Mix!$C$8 -> 0.04 | K21: =I21*J21 -> 0.124 | L21: =I21-K21 -> 2.976 | M21: Assumed | N21: 1 | O21: 0 | P21: $1.55M FY26 budget amendment for 6-month pilot (4 vehicles + paratransit). That's a budget appropriation, not the signed contract value. | Q21: S13
A22: 18 | B22: University Park, TX | C22: Via | D22: 2026-04-07 | E22: Post | F22: Turnkey | G22: 1.06 | H22: 12 | I22: =IF(H22=0,0,G22/H22*12) -> 1.06 | J22: =Updated_Mix!$C$8 -> 0.04 | K22: =I22*J22 -> 0.0424 | L22: =I22-K22 -> 1.0176 | M22: Assumed | N22: 0 | O22: 0 | P22: Tabled, then CANCELLED after voters stayed in DART. Excluded. | Q22: S14
A23: 19 | B23: Union County, NJ | C23: River North Transit LLC | D23: 2026-06 | E23: Post | F23: Turnkey | G23: 0 | H23: 12 | I23: =IF(H23=0,0,G23/H23*12) -> 0 | J23: =Updated_Mix!$C$8 -> 0.04 | K23: =I23*J23 -> 0 | L23: =I23-K23 -> 0 | M23: Assumed | N23: 0 | O23: 0 | P23: 1-yr pilot; Via supplies vehicles, drivers, tech, customer service, maintenance. Value not disclosed. | Q23: S16
A24: 20 | B24: Douglas County, CO – Link On Demand Castle Rock | C24: River North Transit LLC | D24: 2026-07-14 | E24: Post | F24: Turnkey | G24: 1.99172 | H24: 12 | I24: =IF(H24=0,0,G24/H24*12) -> 1.99172 | J24: =Updated_Mix!$C$8 -> 0.04 | K24: =I24*J24 -> 0.0796688 | L24: =I24-K24 -> 1.9120512 | M24: Assumed | N24: 1 | O24: 0 | P24: MSA + initial scope $1,991,720; 2-yr contract + 3 one-yr options; ~$2M/yr; $33–40 per ride. | Q24: S17
A25: 21 | B25: Cobb County, GA – microtransit expansion | C25: Via | D25: 2026-09 (consent agenda) | E25: Post | F25: Turnkey | G25: 6.3 | H25: 24 | I25: =IF(H25=0,0,G25/H25*12) -> 3.15 | J25: =Updated_Mix!$C$8 -> 0.04 | K25: =I25*J25 -> 0.126 | L25: =I25-K25 -> 3.024 | M25: Assumed | N25: 1 | O25: 0 | P25: $6.3M total: Acworth/Kennesaw (2 yrs) + Mableton (1 yr). Split unknown, so annualized over 24 months (conservative). Mostly state funds. | Q25: S18
A26: 22 | B26: Jersey City, NJ – Via service cut | C26: Via | D26: 2026-07-01 | E26: Post | F26: Reduction | G26: -4 | H26: 12 | I26: =IF(H26=0,0,G26/H26*12) -> -4 | J26: 0 | K26: =I26*J26 -> 0 | L26: =I26-K26 -> -4 | M26: Assumed | N26: 1 | O26: 0 | P26: City cut Via hours roughly in half and ended Saturday service: ~$4M/yr savings. A services-hours cut; software is kept. | Q26: S19
A27: 23 | B27: Garner, NC – feasibility study | C27: Via | D27: 2026 | E27: Post | F27: Consulting (one-time) | G27: 0 | H27: 2 | I27: =IF(H27=0,0,G27/H27*12) -> 0 | J27: 1 | K27: =I27*J27 -> 0 | L27: =I27-K27 -> 0 | M27: Assumed | N27: 0 | O27: 0 | P27: 60-day feasibility contract. One-time planning/consulting, value n/a. | Q27: S22
B29: Pre-window turnkey reference set: $-weighted services share | I29: =SUMIFS(L5:L27,E5:E27,"Pre",F5:F27,"Turnkey")/SUMIFS(I5:I27,E5:E27,"Pre",F5:F27,"Turnkey") -> 0.97936566
B30: Pre-window, all rows incl. software-only: $-weighted services share | I30: =SUMIFS(L5:L27,E5:E27,"Pre")/SUMIFS(I5:I27,E5:E27,"Pre") -> 0.97125373
B31: Why the raw contract sample overstates services vs Bleecker's 72%: public records over-sample big turnkey deals, so the sample has to be re-weighted to Via's customer base (see Updated_Mix, section 4).

Sheet Updated_Mix
B1: Updated software/services mix: Bleecker baseline + post-Dec-2025 contracts
B3: 1) Baseline (Bleecker, Dec 16, 2025)
B4: Run-rate revenue base at Bleecker date: Q4'25 ARR ($mm) | C4: 476
B5: Also: FY2025 revenue ($mm), for reference | C5: =Margin_Inputs!B9 -> 434.337
B6: Bleecker services share | C6: 0.72
B7: Baseline services $ / software $ | C7: =C4*C6 -> 342.72 | D7: =C4-C7 -> 133.28
B8: Turnkey contracts: software % of contract value | C8: 0.04
B10: 2) Scenario A: add identified public contracts (Include = 1)
B11: Item | C11: Services $ | D11: Software $ | E11: Total $
B12: Baseline | C12: =C7 -> 342.72 | D12: =D7 -> 133.28 | E12: =C12+D12 -> 476
B13: New turnkey wins (annualized) | C13: =SUMIFS(Contracts!L5:L27,Contracts!N5:N27,1,Contracts!F5:F27,"<>Reduction") -> 17.175049 | D13: =SUMIFS(Contracts!K5:K27,Contracts!N5:N27,1,Contracts!F5:F27,"<>Reduction") -> 0.71562704 | E13: =C13+D13 -> 17.890676
B14: Reductions (Jersey City) | C14: =SUMIFS(Contracts!L5:L27,Contracts!N5:N27,1,Contracts!F5:F27,"Reduction") -> -4 | D14: =SUMIFS(Contracts!K5:K27,Contracts!N5:N27,1,Contracts!F5:F27,"Reduction") -> 0 | E14: =C14+D14 -> -4
B15: Updated total | C15: =SUM(C12:C14) -> 355.89505 | D15: =SUM(D12:D14) -> 133.99563 | E15: =C15+D15 -> 489.89068
B17: New-contract-only services share (flow, excl. reductions) | D17: =IF(E13=0,0,C13/E13) -> 0.96
B18: Net new ACV identified ($mm) | D18: =E13+E14 -> 13.890676
B24: Scenario A: updated services share | D24: =C15/E15 -> 0.72647851
B25: Change vs Bleecker (pts) | D25: =D24-C6 -> 0.0064785112
B27: 3) Scenario B: A, but replace possible network deals with mgmt's disclosed total
B28: Mgmt: 4 network deals won in 2026, >$40M total ACV (Q1'26 call) | C28: 40
B29: Network deals software % (turnkey) | C29: =C8 -> 0.04
B30: Identified A contracts NOT flagged as possible network ($) | C30: =SUMIFS(Contracts!L5:L27,Contracts!N5:N27,1,Contracts!O5:O27,0) -> 5.5867347 | D30: =SUMIFS(Contracts!K5:K27,Contracts!N5:N27,1,Contracts!O5:O27,0) -> 0.39944728
B31: Network deals | C31: =C28*(1-C29) -> 38.4 | D31: =C28*C29 -> 1.6
B32: Updated total (baseline + rows 30–31) | C32: =C12+C30+C31 -> 386.70673 | D32: =D12+D30+D31 -> 135.27945 | E32: =C32+D32 -> 521.98618
B33: Scenario B: updated services share | D33: =C32/E32 -> 0.74083711
B36: 4) Scenario C: roll forward to latest run-rate (Q2'26 ARR)
B37: Q2'26 ARR ($mm) | C37: 543
B38: Growth since baseline explained by Scenario B adds | C38: =E32-C4 -> 45.986182
B39: Residual (organic expansion, unlisted wins, Downtowner, FX) | C39: =C37-E32 -> 21.013818
B40: Services share assumed on residual | C40: 0.72
B41: Note: part of Scenario B ACV hasn't launched yet (mgmt: H2 launches), so C38 can exceed what's in Q2 ARR. If the residual is negative, treat C as an upper bound.
B42: Rolled-forward services $ / software $ | C42: =C32+C39*C40 -> 401.83668 | D42: =D32+C39*(1-C40) -> 141.16332 | E42: =C42+D42 -> 543
B44: Scenario C: services share at Q2'26 run-rate | D44: =C42/E42 -> 0.74003073
B47: 5) Cross-check against the financials (Q2 2026)
B48: Financial-implied services share at base services GM | D48: =Margin_Decomp!I16 -> 0.69204316
B49: Services GM needed to match Scenario A share | D49: =1-Margin_Decomp!I13/(D24*Margin_Decomp!I11) -> 0.25697229
B50: Software GM implied at that point | D50: =(Margin_Decomp!I11*(1-D24)-Margin_Decomp!I14)/(Margin_Decomp!I11*(1-D24)) -> 0.81544778
B51: Services GM needed to match Scenario B share | D51: =1-Margin_Decomp!I13/(D33*Margin_Decomp!I11) -> 0.27137335
B54: 6) Implied customer economics at Bleecker-style mix (Q2'26)
B55: Customers (Q2'26) | C55: 847
B56: Share of customers buying services (mgmt: ~20%) | C56: 0.2
...

Sheet Sources
A1: Sources
A2: Primary pages (SEC, council sites) were blocked from this environment. Figures come from search-engine extracts of these pages, so verify key numbers against the originals before presenting.
A4: ID | B4: Description | C4: URL
A5: S1 | B5: Via S-1/A (FY2024 revenue $337.6M; FY2024 cost of revenue split) | C5: https://www.sec.gov/Archives/edgar/data/1603015/000160301525000012/viatransportationinc-sx1a.htm
A6: S2 | B6: Via 10-Q Q3 2025 (Q3 and 9M 2025 cost of revenue split; H1 2025 figures) | C6: https://www.sec.gov/Archives/edgar/data/1603015/000160301525000042/via-20250930.htm
A7: S3 | B7: Via 10-K FY2025 (FY2025 revenue $434.337M; FY cost of revenue split) | C7: https://www.sec.gov/Archives/edgar/data/1603015/000160301526000008/via-20251231.htm
A8: S4 | B8: Via 10-Q Q1 2026 | C8: https://www.sec.gov/Archives/edgar/data/0001603015/000160301526000014/via-20260331.htm
A9: S5 | B9: Via 10-Q Q2 2026 | C9: https://www.sec.gov/Archives/edgar/data/0001603015/000160301526000026/via-20260630.htm
A10: S6 | B10: Via Q4/FY2025 press release (ARR $476M) | C10: https://www.sec.gov/Archives/edgar/data/1603015/000160301526000002/viaq425pressrelease.htm
A11: S7 | B11: Via Q2 2026 press release (ARR $543M, adj. GM 41%) | C11: https://www.sec.gov/Archives/edgar/data/1603015/000160301526000027/viaq226pressrelease.htm
A12: S8 | B12: Bleecker Street Research, 'Via Transportation (VIA): Road to Nowhere' (Dec 16, 2025) | C12: https://www.bleeckerstreetresearch.com/research/via
A13: S9 | B13: Yahoo Finance / Insider Monkey summary of Bleecker bear case | C13: https://finance.yahoo.com/news/via-transportation-inc-via-bear-133548863.html
A14: S10 | B14: Investing.com: stock falls after short report | C14: https://www.investing.com/news/stock-market-news/via-transportation-stock-falls-after-short-seller-questions-business-model-93CH-4552465
A15: S11 | B15: Plano council item ($3,952,247, 6 months + three 1-yr renewals) | C15: https://content.civicplus.com/api/assets/tx-plano/a163970f-6ef0-4df2-80fa-dfefc1bc37be
... A29: S25 | B29: UK Contracts Finder: TfL Dial-a-Ride software, £2,307,950, Dec 2022–Dec 2027 | C29: https://www.contractsfinder.service.gov.uk/Notice/eba395d5-84f0-449e-8e22-be61afd32fe4
A30: S26 | B30: User research notes (VIA_1.pdf): Arlington, DCTA, King County, Mobile, New Braunfels, Miami-Dade, Gastonia, Passaic, Q4'25 Texas example
